Workbook

Sheet Cover
A1: Anchor & QIB Economics Calculator
A2: Parshwanath Capital Ventures Fund | SEBI Registered CAT III AIF | IN/AIF3/25-26/2108 | Fund Manager: CA Deep Dalal | Sponsor: Jignesh Shah
A4: Purpose: size the anchor pool, estimate our discretionary allotment, model exits at the 30/90-day
A5: lock-in expiries, compare with a non-anchor QIB bid sold on listing day, and map supply overhang.
A7: How to use: 1) Fill every blue cell on 'Inputs' from the RHP (cite the page in column F).
A8: 2) Read 'Allocation' (pool, allotment, scenario returns, exit-route check).
A9: 3) Fill 'Overhang' rows from the RHP capital-structure / lock-in table.
A11: Colours: blue = input | black = formula | green = link from another sheet | yellow = key cell.
A12: Units: Rs crore unless stated. Share counts on 'Overhang' are in lakh.
A14: Anchor allocation is DISCRETIONARY (issuer + BRLM). A favourable call is not an allotment.
A15: Anchor shares are locked in: 50% for 30 days and 50% for 90 days from allotment.
A16: Returns are pre-tax. Tax character for a CAT III AIF depends on the PPM; refer out.
... A31: Investor grievances: fundmanager@parshwanath.in. Complaints may also be lodged with SEBI through SCORES at https://scores.sebi.gov.in.

Sheet Inputs
A1: Inputs - from the offer document (blue cells only)
A2: Parshwanath Capital Ventures Fund | SEBI Registered CAT III AIF | IN/AIF3/25-26/2108 | Fund Manager: CA Deep Dalal | Sponsor: Jignesh Shah
B3: Item | C3: Value | D3: Unit | E3: Hint / page cite
B4: Issue
B5: Issuer | C5: Maxwell Engineering Solutions Limited | E5: Name as per RHP
B6: Platform | C6: SME | E6: Mainboard / SME
B7: Final offer price | C7: 158 | D7: Rs/share
B8: Anchor allocation price | C8: 158 | D8: Rs/share | E8: If offer price > anchor price, anchors pay the difference; if lower, no refund
B9: Total issue size | C9: 57.64 | D9: Rs cr | E9: Fresh + OFS
B10: Employee reservation | C10: 0 | D10: Rs cr
B11: Shareholder reservation | C11: 0 | D11: Rs cr
B13: Net-offer split (confirm from 'Offer Structure' chapter)
B14: QIB portion | C14: 0.5 | E14: Reg 6(1): not more than 50%; Reg 6(2): at least 75%
B15: Non-institutional portion | C15: 0.15
B16: Retail portion | C16: 0.35
B17: Anchor share of QIB portion | C17: 0.6 | E17: Maximum 60% of the QIB portion
B18: Anchor reserved: domestic MFs | C18: 0.3333 | E18: One-third of anchor portion
B19: Anchor reserved: insurers & pension funds | C19: 0.0667 | E19: Per current ICDR amendment - CONFIRM split from the offer document
B20: Net QIB reserved: MFs | C20: 0.05 | E20: 5% of net QIB portion
B22: Our bid
B23: Minimum anchor application | C23: 10 | D23: Rs cr | E23: Mainboard Rs 10 cr - confirm platform limit in the offer document
B24: Our anchor bid | C24: 25 | D24: Rs cr
B25: Assumed allotment as % of bid | C25: 0.6 | E25: Discretionary - assumption, not entitlement
B26: Alternative: non-anchor QIB (ASBA) bid | C26: 25 | D26: Rs cr
B27: Expected QIB (ex-anchor) subscription | C27: 50 | E27: Allotment roughly proportionate: bid / subscription
B28: Days ASBA funds blocked | C28: 6 | D28: days | E28: Issue open to listing
B30: Dates and costs
B31: Anchor bid / pay-in date | C31: 46324 | E31: One working day before issue opens
B32: Allotment date (basis of allotment) | C32: 46330 | E32: Lock-in runs from this date
B33: Listing date | C33: 46332
B34: Lock-in tranche 1 share | C34: 0.5
B35: Lock-in tranche 1 days | C35: 30 | D35: days
B36: Lock-in tranche 2 days | C36: 90 | D36: days
B37: Cost of funds / opportunity cost | C37: 0.09 | D37: p.a. | E37: Anchor money is PAID, not blocked
B38: Exit transaction cost (brokerage+STT+other) | C38: 0.0025 | E38: On sale value
B39: Planned exit route | C39: Lock-in expiry (30/90 days)
B41: Price path vs offer price (illustrative)
B42: Scenario | C42: Listing day | D42: Day 30 | E42: Day 90
B43: Bear
B44: Neutral
...

Sheet Allocation
A1: Anchor pool, our allotment, and exit returns
A2: Parshwanath Capital Ventures Fund | SEBI Registered CAT III AIF | IN/AIF3/25-26/2108 | Fund Manager: CA Deep Dalal | Sponsor: Jignesh Shah
B4: Issue structure (Rs cr)
B5: Net offer | C5: ='Inputs'!$C$9-'Inputs'!$C$10-'Inputs'!$C$11
B6: QIB portion | C6: ='Allocation'!$C$5*'Inputs'!$C$14
B7: Non-institutional portion | C7: ='Allocation'!$C$5*'Inputs'!$C$15
B8: Retail portion | C8: ='Allocation'!$C$5*'Inputs'!$C$16
B9: Split check (must total 100%) | C9: =IF(ABS('Inputs'!$C$14+'Inputs'!$C$15+'Inputs'!$C$16-1)<0.0001,"OK","RED: portions do not total 100%")
B10: Anchor portion | C10: ='Allocation'!$C$6*'Inputs'!$C$17
B11: Anchor cap check | C11: =IF('Inputs'!$C$17<=0.6,"OK","RED: anchor above 60% of QIB")
B12: of which reserved for domestic MFs | C12: ='Allocation'!$C$10*'Inputs'!$C$18
B13: of which reserved for insurers & pension funds | C13: ='Allocation'!$C$10*'Inputs'!$C$19
B14: open anchor pool (where an AIF competes) | C14: ='Allocation'!$C$10-'Allocation'!$C$12-'Allocation'!$C$13
B15: Net QIB (after anchor) | C15: ='Allocation'!$C$6-'Allocation'!$C$10
B16: of which reserved for MFs | C16: ='Allocation'!$C$15*'Inputs'!$C$20
B17: Anchor book size (lakh shares) | C17: ='Allocation'!$C$10*100/'Inputs'!$C$8
B19: Our anchor allotment
B20: Our bid as % of open anchor pool | C20: ='Inputs'!$C$24/'Allocation'!$C$14
B21: Bid size check | C21: =IF('Inputs'!$C$24<'Inputs'!$C$23,"RED: below minimum anchor application",IF('Inputs'!$C$24>'Allocation'!$C$14,"RED: bid exceeds open anchor pool","OK"))
B22: Assumed allotment (Rs cr) | C22: =MIN('Inputs'!$C$24*'Inputs'!$C$25,'Allocation'!$C$14)
B23: Effective cost per share | C23: =MAX('Inputs'!$C$8,'Inputs'!$C$7) | D23: Rs | E23: Anchors top up if offer price exceeds anchor price
B24: Shares allotted | C24: =ROUNDDOWN('Allocation'!$C$22*10^7/'Inputs'!$C$8,0)
B25: Total cost (Rs cr) | C25: ='Allocation'!$C$24*'Allocation'!$C$23/10^7
B26: Tranche 1 shares | C26: =ROUNDDOWN('Allocation'!$C$24*'Inputs'!$C$34,0)
B27: Tranche 2 shares | C27: ='Allocation'!$C$24-'Allocation'!$C$26
B28: Tranche 1 free date | C28: ='Inputs'!$C$32+'Inputs'!$C$35
B29: Tranche 2 free date | C29: ='Inputs'!$C$32+'Inputs'!$C$36
B30: Days funds deployed - tranche 1 | C30: ='Allocation'!$C$28-'Inputs'!$C$31
B31: Days funds deployed - tranche 2 | C31: ='Allocation'!$C$29-'Inputs'!$C$31
B32: Funding cost (Rs cr) | C32: =('Allocation'!$C$26*'Allocation'!$C$30+'Allocation'!$C$27*'Allocation'!$C$31)*'Allocation'!$C$23/10^7*'Inputs'!$C$37/365
B33: Weighted days deployed | C33: =('Allocation'!$C$26*'Allocation'!$C$30+'Allocation'!$C$27*'Allocation'!$C$31)/'Allocation'!$C$24
B35: Exit-route consistency
B36: Anchor bid vs planned exit | C36: =IF('Inputs'!$C$39="Listing day","INCONSISTENT: anchor shares are locked in ("&TEXT('Inputs'!$C$34,"0%")&" for "&'Inputs'!$C$35&" days, rest for "&'Inputs'!$C$36&" days) and cannot be sold on listing day. Bid as non-anchor QIB or change the exit plan.","OK: exit plan is compatible with anchor lock-in")
B37: Allotment note | C37: Anchor allotment is discretionary; there is no proportionate entitlement.
B39: Scenario returns - ANCHOR route (exit at lock-in expiry)
B40: Line | C40: Bear | D40: Neutral | E40: Bull
B41: Listing-day price (Rs) | C41: ='Inputs'!$C$7*(1+Inputs!$C$43) | D41: ='Inputs'!$C$7*(1+Inputs!$C$44) | E41: ='Inputs'!$C$7*(1+Inputs!$C$45)
B42: Day-30 price (Rs) | C42: ='Inputs'!$C$7*(1+Inputs!$D$43) | D42: ='Inputs'!$C$7*(1+Inputs!$D$44) | E42: ='Inputs'!$C$7*(1+Inputs!$D$45)
B43: Day-90 price (Rs) | C43: ='Inputs'!$C$7*(1+Inputs!$E$43) | D43: ='Inputs'!$C$7*(1+Inputs!$E$44) | E43: ='Inputs'!$C$7*(1+Inputs!$E$45)
B44: Mark-to-market on listing day, locked (Rs cr) | C44: ='Allocation'!$C$24*C41/10^7-'Allocation'!$C$25 | D44: ='Allocation'!$C$24*D41/10^7-'Allocation'!$C$25 | E44: ='Allocation'!$C$24*E41/10^7-'Allocation'!$C$25
...

Sheet Overhang
A1: Supply-overhang calendar (shares in lakh)
A2: Parshwanath Capital Ventures Fund | SEBI Registered CAT III AIF | IN/AIF3/25-26/2108 | Fund Manager: CA Deep Dalal | Sponsor: Jignesh Shah
B4: Total post-issue shares (lakh) | C4: 137
B5: Free float at listing (lakh) | C5: =C4-SUM(C9:C15)
B6: Free float as % of total | C6: =C5/C4
B8: Category | C8: Shares (lakh) | D8: Lock-in days from allotment | E8: Release date | F8: Free float just before release | G8: Release as % of float | H8: Cumulative released | I8: Flag | J8: Page cite / note
B9: Anchor - tranche 1 | C9: ='Allocation'!$C$17*'Inputs'!$C$34 | D9: ='Inputs'!$C$35 | E9: ='Inputs'!$C$32+D9 | F9: =$C$5+SUMIF($E$9:$E$15,"<"&E9,$C$9:$C$15) | G9: =IF(F9>0,C9/F9,0) | H9: =SUMIF($E$9:$E$15,"<="&E9,$C$9:$C$15) | I9: =IF(C9=0,"-",IF(G9>0.25,"RED: large cliff vs float",IF(G9>0.1,"AMBER: watch","OK"))) | J9: Whole anchor book, not only our allotment
B10: Anchor - tranche 2 | C10: ='Allocation'!$C$17*(1-'Inputs'!$C$34) | D10: ='Inputs'!$C$36 | E10: ='Inputs'!$C$32+D10 | F10: =$C$5+SUMIF($E$9:$E$15,"<"&E10,$C$9:$C$15) | G10: =IF(F10>0,C10/F10,0) | H10: =SUMIF($E$9:$E$15,"<="&E10,$C$9:$C$15) | I10: =IF(C10=0,"-",IF(G10>0.25,"RED: large cliff vs float",IF(G10>0.1,"AMBER: watch","OK")))
B11: Promoters' minimum contribution (20% of post-issue capital) | C11: 27.4 | D11: 1095 | E11: ='Inputs'!$C$32+D11 | F11: =$C$5+SUMIF($E$9:$E$15,"<"&E11,$C$9:$C$15) | G11: =IF(F11>0,C11/F11,0) | H11: =SUMIF($E$9:$E$15,"<="&E11,$C$9:$C$15) | I11: =IF(C11=0,"-",IF(G11>0.25,"RED: large cliff vs float",IF(G11>0.1,"AMBER: watch","OK"))) | J11: SEBI ICDR (SME): three years
E12: ='Inputs'!$C$32+D12 | F12: =$C$5+SUMIF($E$9:$E$15,"<"&E12,$C$9:$C$15) | G12: =IF(F12>0,C12/F12,0) | H12: =SUMIF($E$9:$E$15,"<="&E12,$C$9:$C$15) | I12: =IF(C12=0,"-",IF(G12>0.25,"RED: large cliff vs float",IF(G12>0.1,"AMBER: watch","OK")))
E13: ='Inputs'!$C$32+D13 | F13: =$C$5+SUMIF($E$9:$E$15,"<"&E13,$C$9:$C$15) | G13: =IF(F13>0,C13/F13,0) | H13: =SUMIF($E$9:$E$15,"<="&E13,$C$9:$C$15) | I13: =IF(C13=0,"-",IF(G13>0.25,"RED: large cliff vs float",IF(G13>0.1,"AMBER: watch","OK")))
E14: ='Inputs'!$C$32+D14 | F14: =$C$5+SUMIF($E$9:$E$15,"<"&E14,$C$9:$C$15) | G14: =IF(F14>0,C14/F14,0) | H14: =SUMIF($E$9:$E$15,"<="&E14,$C$9:$C$15) | I14: =IF(C14=0,"-",IF(G14>0.25,"RED: large cliff vs float",IF(G14>0.1,"AMBER: watch","OK")))
E15: ='Inputs'!$C$32+D15 | F15: =$C$5+SUMIF($E$9:$E$15,"<"&E15,$C$9:$C$15) | G15: =IF(F15>0,C15/F15,0) | H15: =SUMIF($E$9:$E$15,"<="&E15,$C$9:$C$15) | I15: =IF(C15=0,"-",IF(G15>0.25,"RED: large cliff vs float",IF(G15>0.1,"AMBER: watch","OK")))
B17: A small float meeting a large release is a price event unrelated to the business. Re-key rows from the RHP 'Capital Structure' lock-in table.
