Workbook

Sheet Cover
A1: DRHP / RHP Screening Checklist
A2: Parshwanath Capital Ventures Fund | SEBI Registered CAT III AIF | IN/AIF3/25-26/2108 | Fund Manager: CA Deep Dalal | Sponsor: Jignesh Shah
A4: A DRHP is a screen; an RHP is a decision. Record the stage on 'Basis' first.
A5: Order: Basis > Quick Metrics (auto-flags) > Forensic Checks > Work Blocks > Data Gaps > Scorecard.
A6: Two rules: never invent a figure (leave blank, log it in Data Gaps); never draft disclaimer text.
A7: Every figure as restated, cited to the printed page. Watch for three page-numbering blocks.
A8: If the restated-financials annexure is image-only, OCR to locate but read the image to cite.
A9: Thresholds in grey cells on 'Quick Metrics' are house defaults and editable.
A11: Colours: blue = input | black = formula | yellow = key cell.
A12: Issuer build: figures from the offer document (page cites in notes). BLANK cell = declared data gap.
A14: For information only. Not an offer, solicitation or recommendation, and not investment advice or a research report. The Fund may hold or bid for securities of issuers discussed. Investments in securities market are subject to market risks. Read all the related documents carefully before investing. Registration granted by SEBI in no way guarantees performance of the Fund or provides any assurance of returns to investors.
A16: Disclaimer and disclosures
... A25: Investor grievances: fundmanager@parshwanath.in. Complaints may also be lodged with SEBI through SCORES at https://scores.sebi.gov.in.

Sheet Basis
A1: Basis and staleness banner
A2: Parshwanath Capital Ventures Fund | SEBI Registered CAT III AIF | IN/AIF3/25-26/2108 | Fund Manager: CA Deep Dalal | Sponsor: Jignesh Shah
B4: Document
B5: Issuer | C5: Sai Infinium Limited
B6: Platform | C6: Mainboard
B7: Stage | C7: DRHP
B8: Document date | C8: 46289
B9: Audited financials up to | C9: 46112
B10: Today | C10: =TODAY()
B11: Staleness (days since audited period end) | C11: ='Basis'!$C$10-'Basis'!$C$9
B12: Staleness flag | C12: =IF('Basis'!$C$11>365,"RED: audited record over a year old - commit no capital until the RHP is read",IF('Basis'!$C$11>180,"AMBER: RHP must carry financials no more than six months stale","OK"))
B13: Price band announced? | C13: No
B14: Book running lead manager(s) | C14: Fedex Securities Private Limited; Neomile Capital Advisors Private Limited (marketing only) | E14: Compile BRLM track record (CIR/MIRSD/1/2012)
B15: Figures from outside the offer document | C15: merchant-banker section only (named secondary sources, unverified); issuer analysis is from the DRHP
B17: Trade being underwritten
B18: Bid category | C18: Anchor
B19: Exit route underwritten | C19: 2-3 year hold (assumed) | E19: Ask per issuer; default is the 2-3 year hold
B20: Bid category vs exit route | C20: =IF(AND('Basis'!$C$18="Anchor",'Basis'!$C$19="Listing day"),"INCONSISTENT: anchor allotment is locked in 30/90 days - cannot exit on listing day","OK")
B21: Operative valuation tool | C21: =IF('Basis'!$C$19="Listing day","Listing-day framework (DCF used only as a floor test)","DCF governs (intrinsic value over the hold)")

Sheet Quick Metrics
A1: Quick forensic metrics (Rs cr) - restated, as reported; stub never annualised
A2: Parshwanath Capital Ventures Fund | SEBI Registered CAT III AIF | IN/AIF3/25-26/2108 | Fund Manager: CA Deep Dalal | Sponsor: Jignesh Shah
B4: Line item | C4: FY-3 | D4: FY-2 | E4: FY-1 (latest) | F4: Stub (as reported) | G4: Page cite
B5: Revenue from operations | C5: 468.207 | D5: 528.674 | E5: 689.162 | G5: p. 410 (Annexure II)
B6: Other income | C6: 10.701 | D6: 21.25 | E6: 7.271 | G6: p. 448 (Note 26)
B7: Profit before tax | C7: 8.239 | D7: 58.778 | E7: 112.848 | G7: p. 410
B8: Current tax | C8: 3.062 | D8: 9.52 | E8: 26.265 | G8: p. 410 (current tax plus previous-year tax: 30.62 / 95.20 / 262.65 Rs m)
B9: Deferred tax | C9: -0.961 | D9: 5.51 | E9: 4.204 | G9: p. 410 (FY24 is a credit)
B10: PAT | C10: 6.138 | D10: 43.748 | E10: 82.379 | G10: p. 410
B11: Cash flow from operations | C11: -16.548 | D11: -27.677 | E11: 82.525 | G11: p. 411 (Annexure III)
B12: Related-party sales | C12: 13.291 | D12: 312.598 | E12: 159.347 | G12: p. 31 (sale of goods to related parties, Rs m 132.91 / 3,125.98 / 1,593.47)
B13: Related-party purchases (incl. capex) | C13: 5.446 | D13: 205.91 | E13: 125.388 | G13: p. 31 (purchases from related parties, Rs m 54.46 / 2,059.10 / 1,253.88; excludes fixed-asset purchases)
B14: Net worth | C14: 126.85 | D14: 258.666 | E14: 392.31 | G14: p. 409 (total equity; the DRHP's net worth adds back Rs 670.88 m, p. 506)
B15: Trade receivables | C15: 43.635 | D15: 43.688 | E15: 23.258 | G15: p. 441 (Note 10, net of allowance)
B16: Inventory | C16: 107.894 | D16: 197.187 | E16: 78.94 | G16: p. 440 (Note 8)
B17: Trade payables | C17: 25.913 | D17: 123.301 | E17: 49.281 | G17: p. 446 (Note 21)
B18: Contingent liabilities | E18: 88.969 | G18: p. 109 (claims 53.52 + bank guarantees 53.87 + corporate guarantees 782.30 Rs m; commitments of Rs 2,370.81 m are separate)
B19: Goodwill + intangibles | C19: 67.088 | D19: 67.088 | E19: 67.088 | G19: p. 485-486, 498 (debit balance of capital reserve on the 2024 merger, the economic equivalent of goodwill; no goodwill line)
B20: Revaluation reserve | C20: 0 | D20: 0 | E20: 0 | G20: p. 444 (no revaluation reserve)
B22: Single-period inputs (latest)
B23: Top customer % of revenue | E23: 0.1859
B24: Top-10 customers % of revenue | E24: 0.6383
B25: Top supplier % of purchases | E25: 0.1298
B26: Largest state/country % of revenue | E26: 0.9974
B27: Fresh issue net of expenses
B28: Promoter weighted avg cost of acquisition (Rs)
B29: Offer price / cap (Rs) | E29: 90
B31: Auto metrics
B32: Metric | C32: Value | D32: Threshold | E32: Flag | F32: Forensic check / block
B33: Cumulative CFO / cumulative PAT (3 yrs) | C33: =IF(OR(ISBLANK($E$10),ISBLANK($E$11)),"",SUM($C$11:$E$11)/SUM($C$10:$E$10)) | D33: 0.7 | E33: =IF(NOT(ISNUMBER(C33)),"-",IF(C33<D33,"WATCH","OK")) | F33: Check 2 / Block 1
B34: Cumulative cash tax rate (current tax / PBT) | C34: =IF(OR(ISBLANK($E$7),ISBLANK($E$8)),"",SUM($C$8:$E$8)/SUM($C$7:$E$7)) | D34: 0.15 | E34: =IF(NOT(ISNUMBER(C34)),"-",IF(C34<D34,"WATCH","OK")) | F34: Check 3
B35: Deferred tax share of total tax (latest) | C35: =IF(OR(ISBLANK($E$8),ISBLANK($E$9)),"",$E$9/($E$8+$E$9)) | D35: 0.5 | E35: =IF(NOT(ISNUMBER(C35)),"-",IF(C35>D35,"WATCH","OK")) | F35: Check 3
B36: Other income % of PBT (latest) | C36: =IF(OR(ISBLANK($E$6),ISBLANK($E$7)),"",$E$6/$E$7) | D36: 0.15 | E36: =IF(NOT(ISNUMBER(C36)),"-",IF(C36>D36,"WATCH","OK")) | F36: Block 1
B37: RPT sales % of revenue (latest) | C37: =IF(OR(ISBLANK($E$12),ISBLANK($E$5)),"",$E$12/$E$5) | D37: 0.02 | E37: =IF(NOT(ISNUMBER(C37)),"-",IF(C37>D37,"WATCH","OK")) | F37: Block 9 (2% flag)
B38: RPT purchases % of net worth (latest) | C38: =IF(OR(ISBLANK($E$13),ISBLANK($E$14)),"",$E$13/$E$14) | D38: 0.02 | E38: =IF(NOT(ISNUMBER(C38)),"-",IF(C38>D38,"WATCH","OK")) | F38: Check 4 / Block 9
B39: RPT share of revenue growth (FY-2 to latest) | C39: =IF(OR(ISBLANK($E$12),ISBLANK($E$5)),"",IFERROR(($E$12-$D$12)/($E$5-$D$5),"")) | D39: 0.1 | E39: =IF(NOT(ISNUMBER(C39)),"-",IF(C39>D39,"WATCH","OK")) | F39: Block 4
B40: Top customer concentration | C40: =IF(OR(ISBLANK($E$23)),"",$E$23) | D40: 0.5 | E40: =IF(NOT(ISNUMBER(C40)),"-",IF(C40>D40,"WATCH","OK")) | F40: Check 8
B41: Top-10 customer concentration | C41: =IF(OR(ISBLANK($E$24)),"",$E$24) | D41: 0.8 | E41: =IF(NOT(ISNUMBER(C41)),"-",IF(C41>D41,"WATCH","OK")) | F41: Check 8
B42: Top supplier concentration | C42: =IF(OR(ISBLANK($E$25)),"",$E$25) | D42: 0.5 | E42: =IF(NOT(ISNUMBER(C42)),"-",IF(C42>D42,"WATCH","OK")) | F42: Check 8 (supply side)
B43: Geographic concentration | C43: =IF(OR(ISBLANK($E$26)),"",$E$26) | D43: 0.8 | E43: =IF(NOT(ISNUMBER(C43)),"-",IF(C43>D43,"WATCH","OK")) | F43: Check 8
...

Sheet Forensic Checks
A1: Ten forensic checks + regulatory checks
A2: Parshwanath Capital Ventures Fund | SEBI Registered CAT III AIF | IN/AIF3/25-26/2108 | Fund Manager: CA Deep Dalal | Sponsor: Jignesh Shah
A4: # | B4: Check | C4: What to test | D4: Where in the document | E4: Status | F4: Page cite | G4: Finding
A5: 1 | B5: Bonus issue before filing | C5: Basis for Issue Price on pre-bonus count? EPS/NAV restated for all periods (Ind AS 33)? Consistent share count in every chapter? | D5: Capital Structure; Basis for Offer Price; Financials | E5: WATCH | F5: pp. 106, 177, 410, 506 | G5: No bonus issue. The 5-for-1 split (Rs 10 to Rs 2, approved 29-Nov-2025) is applied to all years: EPS Rs 2.80 / 1.59 / 0.43 on 298,327,183 shares at year end. The summary P&L on p. 106 prints the FY26 and FY25 EPS columns the wrong way round (1.59 for FY26, 2.80 for FY25); pp. 177 and 410 carry the correct order and PAT / shares reproduces 2.80 for FY26. A document error, corrected elsewhere in the same document.
A6: 2 | B6: Cash flow statement and CFO vs PAT | C6: Statement present? Cumulative CFO / PAT, standalone and consolidated (see Quick Metrics). | D6: Restated cash flow statement | E6: WATCH | F6: pp. 107-108, 411 | G6: Operating cash flow Rs -165.48 / -276.77 / +825.25 m against PAT 61.38 / 437.48 / 823.79 m; cumulative CFO/PAT 29.0% (383.00 / 1,322.65). Two classification facts cut both ways: (i) the working-capital block includes a Rs 1,189.76 m rise in other non-current assets, mainly capital-goods advances of Rs 1,294.25 m (Note 7, p. 440), so on an investing-activity basis FY26 CFO would be about Rs 2,015 m; (ii) FY26 CFO also includes a Rs 1,182.47 m inventory release, a Rs 740.20 m fall in payables and no cash tax outflow (tax line is a Rs 19.46 m inflow), with Rs 249.29 m of current tax payable at year end. Business reason is documented; read together the FY26 cash figure is not a clean run-rate in either direction.
A7: 3 | B7: Current vs deferred tax | C7: Near-nil current tax? Cumulative cash tax rate vs statutory. | D7: Restated P&L, tax note | E7: WATCH | F7: pp. 447, 411 | G7: Total tax charge 26.5% of cumulative PBT (476.00 / 1,798.65 Rs m) and 18% of it deferred (87.53 Rs m); effective rate 27.0% in FY26. Tax actually paid was Rs 148.65 m in FY25 and Rs 2.27 m in FY24, with a Rs 19.46 m net inflow in FY26 (cumulative Rs 131.46 m, 7.3% of PBT); Rs 249.29 m was payable at 31-Mar-2026 and Rs 21.81 m of interest was provided for short payment of advance tax in FY26 (Note 22, p. 447).
A8: 4 | B8: Related-party capex and proceeds into subsidiaries | C8: Capitalised RP purchases; instrument, rate, tenor, security of funds to subsidiaries; leakage to minorities. | D8: RPT note; Objects | E8: WATCH | F8: pp. 31-34, 110-112, 470-473 | G8: Related-party sales Rs 1,593.47 m (23.1% of FY26 revenue; 59.1% in FY25) and purchases Rs 1,253.88 m (35.7% of purchases; 44.9% in FY25), plus fixed-asset purchases of Rs 537.68 m in FY26 (13.7% of cash capex) and Rs 282.90 m in FY25 (52.4%). Devansh Infinium Private Limited (a corporate promoter, 13.12% holder) is customer (Rs 1,086.91 m), supplier (Rs 456.48 m) and capex vendor (Rs 353.55 m). Payables to related parties Rs 414.42 m = 84% of trade payables (Note 21). The DRHP states all dealings are at arm's length with Audit Committee approval (p. 34) but gives no price benchmark. Proceeds go to the company's own melting shop, not to a related party.
A9: 5 | B9: Objects arithmetic as price floor | C9: Objects / fixed fresh shares, grossed up for expenses and GCP. Floor above fair value? | D9: Objects of the Offer | E9: N.A. | F9: pp. 150-151 | G9: Amount-based fresh issue (Rs 2,800 m) with no fixed share count, so no price floor can be set. The specific object is the melting shop at Rs 2,100 m of net proceeds (75.0% of gross) against a Rs 2,244.20 m project cost, the rest from internal accruals (Rs 30.00 m in FY27, Rs 114.20 m in FY28). General corporate purposes are capped at 25% of gross proceeds (Rs 700 m); offer expenses are [blank] in the DRHP.
A10: 6 | B10: Revaluation reserves | C10: Any non-zero balance. | D10: Other equity note | E10: PASS | F10: p. 444 | G10: No revaluation reserve; other equity is retained earnings Rs 2,150.76 m, securities premium Rs 1,846.57 m and a debit capital reserve of Rs 670.88 m.
A11: 7 | B11: Goodwill vs tangible equity | C11: Goodwill share of equity; purchase accounting changed between documents? | D11: Restated balance sheet | E11: WATCH | F11: pp. 485-486, 498, 506 | G11: No goodwill on the balance sheet, but the 2024 merger of two promoter-group companies (pooling of interests, effective 30-Mar-2024) left a Rs 670.88 m debit balance in capital reserve, 17.1% of book equity of Rs 3,923.10 m (Rs 237.85 m of it is goodwill derecognised on Ind AS transition, p. 498). The DRHP's net worth (Rs 4,593.98 m), NAV per share (Rs 15.40) and RoNW (17.93%) add the Rs 670.88 m back; on book equity NAV is Rs 13.15 and ROE 21.0%. Stated on both bases in this note.
A12: 8 | B12: Concentration - demand AND supply side | C12: Customer, supplier, geography; >80% flags; long-term supply agreement exists? | D12: Business; Risk Factors | E12: WATCH | F12: pp. 29-30, 37-39, 313-315 | G12: Demand: top-10 customers 63.83% / 84.31% / 38.05% of revenue (FY26 / FY25 / FY24); top customer Metarex Global 18.59% (FY25: Devansh Infinium 54.27%). Five of the FY26 top ten (Metarex, Devansh, Falvi Infinium, Sai Endeavours, Axat Impex; Rs 3,375.74 m, 49.0% of revenue) are, or were during part of FY26, on the related-party list. Supply: top-10 suppliers 63.98% of purchases; five of them are related or former related parties. Gujarat is 99.74% of revenue. No long-term contracts with dealers, distributors or suppliers (pp. 29, 315). Reported once, in proportion, as concentration typical of a regional rebar maker plus a group-trading overlay.
A13: 9 | B13: Contingent liabilities and materiality policy | C13: CL vs net worth; is the materiality threshold set to exclude real matters? | D13: Outstanding Litigation; CL note | E13: WATCH | F13: pp. 109, 48, 543 | G13: Contingent liabilities Rs 889.69 m = 22.7% of book equity, of which Rs 782.30 m are corporate guarantees for borrowings of Devansh Infinium (Rs 450 m), Axat Impex LLP (Rs 332.30 m) and Sai Endeavours (Rs 200 m, p. 48); the three borrowers are also customers. Commitments for capital goods Rs 2,370.81 m (p. 440). The Income Tax Department noted in the NCLT order (7-Aug-2024) Rs 844.10 m of FY21 transactions of a merged company with EP Tradelink as unexplained and contemplated reassessment for AY 2021-22; no notice has been received (p. 543). Materiality threshold is the lower of 2% of turnover, 2% of net worth and 5% of average PAT (p. 541).
A14: 10 | B14: Investor presentation vs filed document | C14: Base years, margin definitions, customers, capacity, awards absent from the DRHP; KPIs outside the KPI table. | D14: Investor deck vs DRHP | E14: N.A. | G14: No investor presentation reviewed.
A15: R1 | B15: Auditor qualifications / emphasis of matter | C15: Any qualification, EoM, or CARO adverse remark. | D15: Auditor reports | E15: WATCH | F15: pp. 117-118, 405, 386 | G15: Three statutory-audit changes in FY26: Parshva Shah & Co and Deepak Goyal & Co (joint auditors since 30-Sep-2024) both resigned on 20-Nov-2025 (stated reasons: pre-occupation and increasing commitments); Lahoti & Lahoti were appointed on 24-Nov-2025 and resigned on 14-Mar-2026 before the audit started (pre-occupancy); ANR & Associates were appointed on 16-Mar-2026 and audited FY26. FY25 and FY24 are special-purpose Ind AS statements converted from Indian GAAP accounts audited by Parshva Shah & Co (unmodified, 5-Sep-2025 and 6-Sep-2024). Three CFOs in 9 months (Oct-2024 to Jun-2026). No qualification; reasons for resignation are not company-specific, which the RHP should address.
A16: R2 | B16: CARO 2020 / Rule 11(g) audit trail | C16: Audit-trail compliance reported? | D16: Auditor report annexure | E16: WATCH | F16: pp. 407, 499-502 | G16: The examination report notes CARO 2020 remarks and 'certain instances' on the audit-trail (edit-log) feature for FY26, shown in Part B of Annexure VI (p. 407). The CARO list for FY26 shows quarterly returns filed with Bank of India that differ from the books: stock Rs 1,150.03 m vs Rs 938.11 m in Q1, Rs 789.40 m vs Rs 687.39 m in Q4 (differences Rs 66.43 m to Rs 211.92 m, explained as divisions excluded from the hypothecated stock) and book debts by Rs -80.63 m to +13.28 m (explained as provisional figures submitted before reconciling customer accounts) (p. 499). The FY25 CARO records a customs dispute on a Jan-2022 import of heavy melting scrap, one container still under seizure for used cartridges (p. 501). An earlier DRHP for 19.6 m Rs 10 shares was filed on 2-Apr-2025 and withdrawn before the FY25 audit report was signed (pp. 406, 499).
A17: R3 | B17: Monitoring agency (ICDR Reg 262(1)) | C17: Appointed where required by issue size? | D17: Objects | E17: PASS | F17: p. 173 | G17: Monitoring agency to be appointed (fresh issue above Rs 1,000 m). No debt-repayment object. The melting shop is on owned land (Rs 44.15 m, fully paid, p. 154).
A18: R4 | B18: Mainboard eligibility (Reg 6(1)/6(2)) | C18: Re-perform the eligibility computation; compare to KPI basis. | D18: Other Regulatory and Statutory Disclosures | E18: PASS | F18: p. 571 | G18: Reg 6(1) re-performed: operating profit 1,181.72 / 470.82 / 77.26 Rs m reproduces from PBT less other income plus finance cost (1,128.48 - 72.71 + 125.95 = 1,181.72); three-year average Rs 576.60 m against the Rs 150 m test and positive in each year; net worth above Rs 10 m; monetary assets 7.02% of NTA. The name was last changed on 22-Nov-2024, more than a year before filing. Restated NTA of Rs 3,838.83 m does not equal total equity of Rs 3,923.10 m (difference Rs 84.27 m, unexplained); the test passes on either figure.
A19: R5 | B19: SME (Chapter IX) - post-2025 conditions | C19: OFS cap, selling-holder cap, GCP cap, operating-profit test, no proceeds to repay promoter/RP loans. Confirm against current ICDR text. | D19: Offer structure; Objects | E19: WATCH | F19: pp. 1, 101 | G19: OFS of 12,000,000 shares by Ishu Bansal, about 5.1% of her 235,354,800 shares (below half of her holding). If the 20% OFS ceiling applies, the OFS is within it only at a price of Rs 58.33 or less (12.0 m x P <= 20% x (Rs 2,800 m + 12.0 m x P)); at the Rs 90 reference it would be Rs 1,080 m, 27.8% of a Rs 3,880 m offer. Her weighted average cost of acquisition is below Rs 0.01 and 19,460,000 shares reached her by gift on 6-Mar-2026 (p. 189). Re-test at the RHP price.
A20: R6 | B20: BRLM track record (CIR/MIRSD/1/2012) | C20: Compile from exchange data: issue price, listing gain, current price vs issue price. | D20: BRLM website / exchange data | E20: WATCH | F20: pp. 577-579 | G20: Fedex Securities is the BRLM; Neomile Capital is a marketing-only BRLM and is handling its first public issue. Fedex lists 3 mainboard IPOs in the table: Mukka Proteins (+35.5% at day 30, +65.3% at day 180), Deepak Builders (-23.2%, -30.9%) and Patel Retail (-7.2%, -28.7%), plus 8 SME issues; its full track record is at a website link only (p. 579). Recorded in data/merchant_bankers.json.
A21: R7 | B21: Firm means of finance (Reg 230(1)(e)) | C21: 75% of stated means of finance tied up, excluding issue proceeds? | D21: Objects | E21: WATCH | F21: pp. 150-153, 299, 440, 464 | G21: Project cost of the melting shop is Rs 2,244.20 m (cost report of 17-Aug-2026); quotations are valid for about 12 months from April to July 2026. This object sits beside a larger programme already under way: Rolling Mill 3 (Rs 1,719.51 m incurred, production by 31-Dec-2026), a captive wind-solar plant costing about Rs 4,043 m (Rs 1,747.82 m paid to Opera Energy, completion by 31-Oct-2026) and a Rs 500 m copper smelting plan. Borrowings were Rs 5,024.07 m at 30-Jun-2026 against Rs 3,575.72 m at 31-Mar-2026. The IREDA pledge over promoter shares is not yet created (Rs 5.11 m penalty paid, waived to an extended date, p. 50).

Sheet Work Blocks
A1: Twelve analyst work blocks - work all twelve, report what moves the conclusion
A2: Parshwanath Capital Ventures Fund | SEBI Registered CAT III AIF | IN/AIF3/25-26/2108 | Fund Manager: CA Deep Dalal | Sponsor: Jignesh Shah
A4: Block | B4: Question | C4: Finding | D4: Moves conclusion? | E4: Page cite
A5: 1 Earnings quality | B5: Cumulative CFO / PAT; CFO before and after working capital
A6: 1 Earnings quality | B6: Non-recurring items in other income as % of PBT
A7: 1 Earnings quality | B7: Is the stub period seasonally favourable for this industry?
A8: 2 Working capital | B8: NWC % revenue each period
A9: 2 Working capital | B9: Incremental NWC per Rs of incremental revenue
A10: 2 Working capital | B10: Closing-balance days vs issuer's average-based days
A11: 3 Receivables / payables / inventory | B11: Schedule III ageing: buckets from due date or invoice date?
A12: 3 Receivables / payables / inventory | B12: Provision coverage on old debt
A13: 3 Receivables / payables / inventory | B13: MSME payables and Sec 15/16 interest
A14: 3 Receivables / payables / inventory | B14: Slow-moving inventory
A15: 4 Revenue integrity | B15: Standalone vs consolidated revenue and EPS
A16: 4 Revenue integrity | B16: Related-party contribution to growth
... A44: 12 Industry and competition | B44: Arm's-length transactions in own shares - implied multiple

Sheet Data Gaps
A1: Data gaps - declared holes, never estimated
A2: Parshwanath Capital Ventures Fund | SEBI Registered CAT III AIF | IN/AIF3/25-26/2108 | Fund Manager: CA Deep Dalal | Sponsor: Jignesh Shah
A4: Item | B4: Severity | C4: Why it matters | D4: Source to try (BSE/NSE/MCA/ROC) | E4: Status | F4: Closed in RHP?
A5: BRLM track record compilation | B5: Medium | C5: Required by SEBI circular; usually delegated to the BRLM website

Sheet Scorecard
A1: Forensic scorecard and call
A2: Parshwanath Capital Ventures Fund | SEBI Registered CAT III AIF | IN/AIF3/25-26/2108 | Fund Manager: CA Deep Dalal | Sponsor: Jignesh Shah
B4: ='Basis'!$C$5&" | "&'Basis'!$C$7&" | "&'Basis'!$C$19
B6: Status | C6: Count
B7: PASS | C7: =COUNTIF('Forensic Checks'!$E$5:$E$21,B7)
B8: WATCH | C8: =COUNTIF('Forensic Checks'!$E$5:$E$21,B8)
B9: FAIL | C9: =COUNTIF('Forensic Checks'!$E$5:$E$21,B9)
B10: N.A. | C10: =COUNTIF('Forensic Checks'!$E$5:$E$21,B10)
B11: OPEN | C11: =COUNTIF('Forensic Checks'!$E$5:$E$21,B11)
B13: Auto-metric WATCH flags | C13: =COUNTIF('Quick Metrics'!$E$1:$E$200,"WATCH")
B14: High-severity data gaps open | C14: =COUNTIFS('Data Gaps'!$B$5:$B$29,"High",'Data Gaps'!$E$5:$E$29,"Open")
B15: Staleness | C15: ='Basis'!$C$12
B16: Exit consistency | C16: ='Basis'!$C$20
B18: Screen outcome | C18: =IF(C9>0,"FAIL items present - move to full DD only with explicit reasons",IF(C11>0,"WATCH: "&C11&" checks still open - screen not complete",IF(C8+C13>2,"WATCH: several watch items - full DD required","PASS to full due diligence")))
B20: Call (Subscribe / Avoid / Neutral)
B22: What would change our view (measurable, verifiable against the RHP)
B23: 1.
B24: 2.
B25: 3.
B26: 4.
B27: 5.
B29: For information only. Not an offer, solicitation or recommendation, and not investment advice or a research report. The Fund may hold or bid for securities of issuers discussed. Investments in securities market are subject to market risks. Read all the related documents carefully before investing. Registration granted by SEBI in no way guarantees performance of the Fund or provides any assurance of returns to investors.
