Workbook

Sheet Cover
A1: Peer Comps & Valuation Model
A2: Parshwanath Capital Ventures Fund | SEBI Registered CAT III AIF | IN/AIF3/25-26/2108 | Fund Manager: CA Deep Dalal | Sponsor: Jignesh Shah
A4: Sheets: Assumptions (only input sheet) > Peers > Relative > DCF > ReverseDCF > Sensitivity > Summary.
A5: Scenario toggle: Assumptions!C5 (1 = Bear, 2 = Neutral, 3 = Bull). Every driver needs a rationale and page cite.
A6: DCF and relative values are shown separately, then blended (default 60:40; use 80:20 if no listed peers).
A7: Terminal growth 4.50%. Capex = D&A + k x change in revenue. Terminal reinvestment = g / terminal ROIC.
A8: Bear case excludes the IPO-funded capex object AND its funding. Share count is post-issue, fully diluted.
A9: Peer multiples: P/E, EV/EBITDA, P/B. EV/Sales is deliberately excluded.
A10: Match peers on business model before industry code, and on the same basis (consolidated / standalone).
A11: Upside is reported as % only. Grey market premium never moves fair value.
A13: Colours: blue = input | black = formula | green = link | yellow = key cell.
A14: Issuer build: figures from the offer document (page cites in notes). BLANK cell = declared data gap.
... A27: Investor grievances: fundmanager@parshwanath.in. Complaints may also be lodged with SEBI through SCORES at https://scores.sebi.gov.in.

Sheet Summary
A1: Valuation summary
A2: Parshwanath Capital Ventures Fund | SEBI Registered CAT III AIF | IN/AIF3/25-26/2108 | Fund Manager: CA Deep Dalal | Sponsor: Jignesh Shah
B4: ="Scenario: "&Assumptions!$D$5&" | Issuer: "&'Assumptions'!$C$8
B6: Method | C6: Value / share (Rs) | D6: Upside vs floor | E6: Upside vs cap
B7: DCF | C7: =DCF!C37 | D7: =IFERROR(C7/'Assumptions'!$C$15-1,"") | E7: =IFERROR(C7/'Assumptions'!$C$16-1,"")
B8: Relative | C8: =Relative!F11 | D8: =IFERROR(C8/'Assumptions'!$C$15-1,"") | E8: =IFERROR(C8/'Assumptions'!$C$16-1,"")
B9: Blended (DCF weight per Assumptions) | C9: =IF(ISNUMBER(C8),'Assumptions'!$C$48*C7+(1-'Assumptions'!$C$48)*C8,C7) | D9: =IFERROR(C9/'Assumptions'!$C$15-1,"") | E9: =IFERROR(C9/'Assumptions'!$C$16-1,"")
B11: DCF vs relative divergence | C11: =IFERROR(C7/C8-1,"n.a.")
B12: Divergence flag | C12: =IF(ISNUMBER(C11),IF(ABS(C11)>0.25,"AMBER: DCF and relative diverge by "&TEXT(C11,"0.0%")&" - the divergence is the finding; name its cause","OK"),"n.a.")
B13: Objects floor price | C13: ='Assumptions'!$C$63
B14: Objects floor vs blended value | C14: =IF(ISNUMBER(C13),IF(C13>C9,"RED: objects floor sits above blended fair value","OK"),"n.a.")
B15: Terminal value share | C15: =DCF!C40
B16: WACC - g | C16: =DCF!C41
B17: Terminal ROIC vs WACC | C17: =DCF!C42
B18: Reverse DCF (at cap) | C18: =ReverseDCF!C16
B20: Call (Subscribe / Avoid / Neutral)
B22: Record of all three scenarios (switch Assumptions!C5, paste values here)
C23: Bear | D23: Neutral | E23: Bull
B24: DCF / share
B25: Relative / share
B26: Blended / share
B27: Upside vs cap
B29: Upside is reported as a percentage only. No position sizing. Returns are pre-tax.
B31: For information only. Not an offer, solicitation or recommendation, and not investment advice or a research report. The Fund may hold or bid for securities of issuers discussed. Investments in securities market are subject to market risks. Read all the related documents carefully before investing. Registration granted by SEBI in no way guarantees performance of the Fund or provides any assurance of returns to investors.

Sheet Assumptions
A1: Assumptions - the only input sheet
A2: Parshwanath Capital Ventures Fund | SEBI Registered CAT III AIF | IN/AIF3/25-26/2108 | Fund Manager: CA Deep Dalal | Sponsor: Jignesh Shah
B5: Scenario (1 = Bear, 2 = Neutral, 3 = Bull) | C5: 2 | D5: =CHOOSE($C$5,"Bear","Neutral","Bull")
B7: Issuer and offer
B8: Issuer | C8: Sai Infinium Limited
B9: Financial basis | C9: Standalone | E9: Use the same basis for every peer
B10: Pre-issue shares, fully diluted (post any bonus) | C10: 29.832718 | D10: crore | E10: Check bonus restatement (forensic check 1)
B11: ESOP / convertibles outstanding | C11: 0 | D11: crore
B12: Fresh issue amount (fixed at objects need) | C12: 280 | D12: Rs cr
B13: Fresh shares fixed in DRHP (0 if amount-based) | C13: 0 | D13: crore
B14: OFS shares (no effect on share count) | C14: 1.2 | D14: crore
B15: Price band - floor | C15: 90 | D15: Rs
B16: Price band - cap | C16: 90 | D16: Rs
B17: Valuation reference price | C17: ='Assumptions'!$C$16 | D17: Rs | E17: Defaults to cap; overwrite if needed
B18: Specific objects (excl. GCP and offer expenses) | C18: 210 | D18: Rs cr
B19: Offer expenses as % of fresh issue | C19: 0.05
B20: GCP as % of fresh issue | C20: 0.2 | E20: Check against regulatory cap
B21: IPO-funded capex object | C21: 210 | D21: Rs cr
B22: Share of IPO capex spent in Y1 (rest in Y2) | C22: 0.2
B24: Latest audited year (restated) - never annualise a stub
B25: Revenue from operations | C25: 689.162 | D25: Rs cr
B26: Revenue - prior year | C26: 528.674 | D26: Rs cr
B27: EBITDA (ties to issuer KPI table) | C27: 128.188 | D27: Rs cr
B28: Depreciation & amortisation | C28: 10.016 | D28: Rs cr
B29: PAT | C29: 82.379 | D29: Rs cr
B30: Net worth (pre-issue) | C30: 392.31 | D30: Rs cr
B31: Net debt (borrowings - cash) | C31: 330.625 | D31: Rs cr
B32: Net working capital | C32: 52.917 | D32: Rs cr | E32: Reconcile to Objects-chapter WC table
B33: Net working capital - prior year | C33: 117.574 | D33: Rs cr
B34: Capex (purchase of PPE + intangibles) | C34: 391.978 | D34: Rs cr
B35: Tax rate | C35: 0.2517
B37: Cost of capital (CAPM build-up)
B38: Risk-free rate (10y G-sec) | C38: 0.065
B39: Beta | C39: 1.1
B40: Equity risk premium | C40: 0.07
B41: Size premium | C41: 0.02
B42: Company-specific premium | C42: 0 | E42: 0 by default; up to 1% only for a specific, cited, non-routine risk
B43: Pre-tax cost of debt | C43: 0.1
B44: Target debt / (debt + equity) | C44: 0.2
B45: Terminal growth | C45: 0.045
...

Sheet DCF
A1: Discounted cash flow (FCFF) - selected scenario
A2: Parshwanath Capital Ventures Fund | SEBI Registered CAT III AIF | IN/AIF3/25-26/2108 | Fund Manager: CA Deep Dalal | Sponsor: Jignesh Shah
B3: ="Scenario: "&Assumptions!$D$5
B5: Rs cr | C5: Y0 (actual) | D5: Y1 | E5: Y2 | F5: Y3 | G5: Y4 | H5: Y5
B6: Revenue growth | C6: ='Assumptions'!$C$25/'Assumptions'!$C$26-1 | D6: =Assumptions!$C$67 | E6: =Assumptions!$C$68 | F6: =Assumptions!$C$69 | G6: =Assumptions!$C$70 | H6: =Assumptions!$C$71
B7: Revenue | C7: ='Assumptions'!$C$25 | D7: =C7*(1+D6) | E7: =D7*(1+E6) | F7: =E7*(1+F6) | G7: =F7*(1+G6) | H7: =G7*(1+H6)
B8: EBITDA margin | C8: ='Assumptions'!$C$27/'Assumptions'!$C$25 | D8: =Assumptions!$C$72 | E8: =Assumptions!$C$72 | F8: =Assumptions!$C$72 | G8: =Assumptions!$C$72 | H8: =Assumptions!$C$72
B9: EBITDA | C9: ='Assumptions'!$C$27 | D9: =D7*D8 | E9: =E7*E8 | F9: =F7*F8 | G9: =G7*G8 | H9: =H7*H8
B10: D&A | C10: ='Assumptions'!$C$28 | D10: =D7*'Assumptions'!$C$61 | E10: =E7*'Assumptions'!$C$61 | F10: =F7*'Assumptions'!$C$61 | G10: =G7*'Assumptions'!$C$61 | H10: =H7*'Assumptions'!$C$61
B11: EBIT | C11: =C9-C10 | D11: =D9-D10 | E11: =E9-E10 | F11: =F9-F10 | G11: =G9-G10 | H11: =H9-H10
B12: Tax on EBIT | C12: =C11*'Assumptions'!$C$35 | D12: =D11*'Assumptions'!$C$35 | E12: =E11*'Assumptions'!$C$35 | F12: =F11*'Assumptions'!$C$35 | G12: =G11*'Assumptions'!$C$35 | H12: =H11*'Assumptions'!$C$35
B13: NOPAT | C13: =C11-C12 | D13: =D11-D12 | E13: =E11-E12 | F13: =F11-F12 | G13: =G11-G12 | H13: =H11-H12
B14: Organic capex (D&A + k x dRev) | C14: ='Assumptions'!$C$34 | D14: =D10+'Assumptions'!$C$62*(D7-C7) | E14: =E10+'Assumptions'!$C$62*(E7-D7) | F14: =F10+'Assumptions'!$C$62*(F7-E7) | G14: =G10+'Assumptions'!$C$62*(G7-F7) | H14: =H10+'Assumptions'!$C$62*(H7-G7)
B15: IPO-funded capex | C15: 0 | D15: ='Assumptions'!$C$57*'Assumptions'!$C$22 | E15: ='Assumptions'!$C$57*(1-'Assumptions'!$C$22) | F15: ='Assumptions'!$C$57*0 | G15: ='Assumptions'!$C$57*0 | H15: ='Assumptions'!$C$57*0
B16: Net working capital | C16: ='Assumptions'!$C$32 | D16: =D7*Assumptions!$C$73 | E16: =E7*Assumptions!$C$73 | F16: =F7*Assumptions!$C$73 | G16: =G7*Assumptions!$C$73 | H16: =H7*Assumptions!$C$73
B17: Change in NWC | C17: ='Assumptions'!$C$32-'Assumptions'!$C$33 | D17: =D16-C16 | E17: =E16-D16 | F17: =F16-E16 | G17: =G16-F16 | H17: =H16-G16
B18: Free cash flow to firm | C18: =C13+C10-C14-C15-C17 | D18: =D13+D10-D14-D15-D17 | E18: =E13+E10-E14-E15-E17 | F18: =F13+F10-F14-F15-F17 | G18: =G13+G10-G14-G15-G17 | H18: =H13+H10-H14-H15-H17
B19: Discount factor | D19: =1/(1+'Assumptions'!$C$60)^1 | E19: =1/(1+'Assumptions'!$C$60)^2 | F19: =1/(1+'Assumptions'!$C$60)^3 | G19: =1/(1+'Assumptions'!$C$60)^4 | H19: =1/(1+'Assumptions'!$C$60)^5
B20: PV of FCFF | D20: =D18*D19 | E20: =E18*E19 | F20: =F18*F19 | G20: =G18*G19 | H20: =H18*H19
B22: Terminal growth (g) | C22: ='Assumptions'!$C$45
B23: Terminal ROIC | C23: =Assumptions!$C$74
B24: Terminal reinvestment rate (g / ROIC) | C24: =C22/C23
B25: NOPAT Y6 | C25: =H13*(1+C22)
B26: FCFF Y6 | C26: =C25*(1-C24)
B27: Terminal value at Y5 | C27: =C26/('Assumptions'!$C$60-C22)
B28: PV of terminal value | C28: =C27*H19
B30: Sum of PV, explicit period | C30: =SUM(D20:H20)
B31: Enterprise value | C31: =C30+C28
B32: Terminal value share of EV | C32: =C28/C31
B33: Less: net debt | C33: =-'Assumptions'!$C$31
B34: Add: issue proceeds credited | C34: ='Assumptions'!$C$58
B35: Equity value | C35: =C31+C33+C34
B36: Post-issue diluted shares (crore) | C36: ='Assumptions'!$C$56
B37: DCF value per share (Rs) | C37: =C35/C36
B39: Degeneracy guards
B40: Terminal value share | C40: =IF(C32>1,"DEGENERATE: TV above 100% of EV - fix assumptions, do not report",IF(C32>0.75,"AMBER: TV above 75% of EV - DCF is mostly a terminal guess","OK"))
B41: WACC minus g | C41: =IF('Assumptions'!$C$60-C22<0.02,"RED: WACC - g below 2% - terminal swamps value","OK")
B42: Terminal ROIC vs WACC | C42: =IF(C23<'Assumptions'!$C$60,"RED: terminal ROIC below WACC - growth destroys value","OK")
B43: Explicit-period FCF | C43: =IF(SUM(D18:H18)<0,"AMBER: cumulative explicit FCF negative","OK")
B45: IPO capex adds assets; reflect any revenue it enables in the Neutral/Bull growth rates, with a cite.

Sheet Peers
A1: Peer set - ILLUSTRATIVE peers, replace with real listed comparables
A2: Parshwanath Capital Ventures Fund | SEBI Registered CAT III AIF | IN/AIF3/25-26/2108 | Fund Manager: CA Deep Dalal | Sponsor: Jignesh Shah
B4: Company | C4: Include (Y/N) | D4: Business-model match | E4: Basis | F4: CMP (Rs) | G4: Shares (cr) | H4: Net debt | I4: Revenue | J4: EBITDA | K4: PAT | L4: Net worth | M4: Rev growth | N4: Mcap | O4: EV | P4: P/E | Q4: EV/EBITDA | R4: P/B | S4: EBITDA margin | T4: ROE
B5: Vraj Iron and Steel Ltd | C5: Y | D5: Semi-integrated sponge iron, billets and TMT; named by the issuer (p. 178) | E5: Consolidated (standalone where stated) | F5: 125.88 | G5: 3.2983 | H5: 36.873 | I5: 587.924 | J5: 56.728 | K5: 32.005 | L5: 429.795 | M5: -0.4538 | N5: =IF(F5="","",F5*G5) | O5: =IF(N5="","",N5+H5) | P5: =IF(AND(C5="Y",N(K5)>0),N5/K5,"") | Q5: =IF(AND(C5="Y",N(J5)>0),O5/J5,"") | R5: =IF(AND(C5="Y",N(L5)>0),N5/L5,"") | S5: =IF(N(I5)>0,J5/I5,"") | T5: =IF(N(L5)>0,K5/L5,"")
B6: Rudra Global Infra Products Ltd | C6: Y | D6: TMT bars and long steel; named by the issuer (p. 178) | E6: Consolidated (standalone where stated) | F6: 20.1 | G6: 10.038 | H6: 134.005 | I6: 622.829 | J6: 36.916 | K6: 13.519 | L6: 138.725 | M6: 0.3111 | N6: =IF(F6="","",F6*G6) | O6: =IF(N6="","",N6+H6) | P6: =IF(AND(C6="Y",N(K6)>0),N6/K6,"") | Q6: =IF(AND(C6="Y",N(J6)>0),O6/J6,"") | R6: =IF(AND(C6="Y",N(L6)>0),N6/L6,"") | S6: =IF(N(I6)>0,J6/I6,"") | T6: =IF(N(L6)>0,K6/L6,"")
B7: VMS TMT Ltd (standalone) | C7: Y | D7: Gujarat TMT maker; closest regional peer (p. 178) | E7: Consolidated (standalone where stated) | F7: 47.23 | G7: 4.9626 | H7: 220.861 | I7: 838.557 | J7: 60.676 | K7: 21.034 | L7: 228.133 | M7: 0.4953 | N7: =IF(F7="","",F7*G7) | O7: =IF(N7="","",N7+H7) | P7: =IF(AND(C7="Y",N(K7)>0),N7/K7,"") | Q7: =IF(AND(C7="Y",N(J7)>0),O7/J7,"") | R7: =IF(AND(C7="Y",N(L7)>0),N7/L7,"") | S7: =IF(N(I7)>0,J7/I7,"") | T7: =IF(N(L7)>0,K7/L7,"")
B8: Gallantt Ispat Ltd | C8: Y | D8: Integrated sponge iron, billets, TMT and power; much larger (p. 178) | E8: Consolidated (standalone where stated) | F8: 545.7 | G8: 24.1286 | H8: 42.987 | I8: 4418.922 | J8: 716.444 | K8: 484.268 | L8: 3316.235 | M8: 0.0294 | N8: =IF(F8="","",F8*G8) | O8: =IF(N8="","",N8+H8) | P8: =IF(AND(C8="Y",N(K8)>0),N8/K8,"") | Q8: =IF(AND(C8="Y",N(J8)>0),O8/J8,"") | R8: =IF(AND(C8="Y",N(L8)>0),N8/L8,"") | S8: =IF(N(I8)>0,J8/I8,"") | T8: =IF(N(L8)>0,K8/L8,"")
B9: MSP Steel Power Ltd | C9: N | D9: Integrated steel; P/E 59.12x on ROE 3.28% and net debt 16.5x EBITDA, not meaningful (pp. 178, 183) | E9: Consolidated (standalone where stated) | F9: 33.39 | G9: 56.683 | H9: 2924.119 | I9: 2842.964 | J9: 177.65 | K9: 33.771 | L9: 1030.497 | M9: -0.0214 | N9: =IF(F9="","",F9*G9) | O9: =IF(N9="","",N9+H9) | P9: =IF(AND(C9="Y",N(K9)>0),N9/K9,"") | Q9: =IF(AND(C9="Y",N(J9)>0),O9/J9,"") | R9: =IF(AND(C9="Y",N(L9)>0),N9/L9,"") | S9: =IF(N(I9)>0,J9/I9,"") | T9: =IF(N(L9)>0,K9/L9,"")
B10: VMS Industries Ltd (standalone) | C10: N | D10: Small, EBITDA margin 4.3% and ROE 1.5%; P/E 30x on thin earnings (pp. 178, 183) | E10: Consolidated (standalone where stated) | F10: 18.02 | G10: 2.4473 | H10: 13.496 | I10: 157.431 | J10: 6.748 | K10: 1.463 | L10: 97.158 | M10: -0.4544 | N10: =IF(F10="","",F10*G10) | O10: =IF(N10="","",N10+H10) | P10: =IF(AND(C10="Y",N(K10)>0),N10/K10,"") | Q10: =IF(AND(C10="Y",N(J10)>0),O10/J10,"") | R10: =IF(AND(C10="Y",N(L10)>0),N10/L10,"") | S10: =IF(N(I10)>0,J10/I10,"") | T10: =IF(N(L10)>0,K10/L10,"")
N11: =IF(F11="","",F11*G11) | O11: =IF(N11="","",N11+H11) | P11: =IF(AND(C11="Y",N(K11)>0),N11/K11,"") | Q11: =IF(AND(C11="Y",N(J11)>0),O11/J11,"") | R11: =IF(AND(C11="Y",N(L11)>0),N11/L11,"") | S11: =IF(N(I11)>0,J11/I11,"") | T11: =IF(N(L11)>0,K11/L11,"")
N12: =IF(F12="","",F12*G12) | O12: =IF(N12="","",N12+H12) | P12: =IF(AND(C12="Y",N(K12)>0),N12/K12,"") | Q12: =IF(AND(C12="Y",N(J12)>0),O12/J12,"") | R12: =IF(AND(C12="Y",N(L12)>0),N12/L12,"") | S12: =IF(N(I12)>0,J12/I12,"") | T12: =IF(N(L12)>0,K12/L12,"")
B14: Median (included) | P14: =IF(COUNT(P5:P12)=0,"",MEDIAN(P5:P12)) | Q14: =IF(COUNT(Q5:Q12)=0,"",MEDIAN(Q5:Q12)) | R14: =IF(COUNT(R5:R12)=0,"",MEDIAN(R5:R12)) | S14: =IF(COUNT(S5:S12)=0,"",MEDIAN(S5:S12)) | T14: =IF(COUNT(T5:T12)=0,"",MEDIAN(T5:T12))
B15: Mean (included) | P15: =IF(COUNT(P5:P12)=0,"",AVERAGE(P5:P12)) | Q15: =IF(COUNT(Q5:Q12)=0,"",AVERAGE(Q5:Q12)) | R15: =IF(COUNT(R5:R12)=0,"",AVERAGE(R5:R12)) | S15: =IF(COUNT(S5:S12)=0,"",AVERAGE(S5:S12)) | T15: =IF(COUNT(T5:T12)=0,"",AVERAGE(T5:T12))
B16: Min | P16: =IF(COUNT(P5:P12)=0,"",MIN(P5:P12)) | Q16: =IF(COUNT(Q5:Q12)=0,"",MIN(Q5:Q12)) | R16: =IF(COUNT(R5:R12)=0,"",MIN(R5:R12)) | S16: =IF(COUNT(S5:S12)=0,"",MIN(S5:S12)) | T16: =IF(COUNT(T5:T12)=0,"",MIN(T5:T12))
B17: Max | P17: =IF(COUNT(P5:P12)=0,"",MAX(P5:P12)) | Q17: =IF(COUNT(Q5:Q12)=0,"",MAX(Q5:Q12)) | R17: =IF(COUNT(R5:R12)=0,"",MAX(R5:R12)) | S17: =IF(COUNT(S5:S12)=0,"",MAX(S5:S12)) | T17: =IF(COUNT(T5:T12)=0,"",MAX(T5:T12))
B19: Company | C19: Include (Y/N) | D19: Business-model match | E19: Basis | F19: CMP (Rs) | G19: Shares (cr) | H19: Net debt | I19: Revenue | J19: EBITDA | K19: PAT | L19: Net worth | M19: Rev growth | N19: Mcap | O19: EV | P19: P/E | Q19: EV/EBITDA | R19: P/B | S19: EBITDA margin | T19: ROE
B20: Issuer at floor (post-issue) | C20: Y | E20: ='Assumptions'!$C$9 | F20: ='Assumptions'!$C$15 | G20: ='Assumptions'!$C$10+'Assumptions'!$C$11+IF('Assumptions'!$C$13>0,'Assumptions'!$C$13,'Assumptions'!$C$12/F20) | H20: ='Assumptions'!$C$31-'Assumptions'!$C$55 | I20: ='Assumptions'!$C$25 | J20: ='Assumptions'!$C$27 | K20: ='Assumptions'!$C$29 | L20: ='Assumptions'!$C$30+'Assumptions'!$C$55 | M20: ='Assumptions'!$C$25/'Assumptions'!$C$26-1 | N20: =F20*G20 | O20: =N20+H20 | P20: =IF(K20>0,N20/K20,"n.m.") | Q20: =IF(J20>0,O20/J20,"n.m.") | R20: =IF(L20>0,N20/L20,"n.m.") | S20: =J20/I20 | T20: =K20/L20
B21: Issuer at cap (post-issue) | C21: Y | E21: ='Assumptions'!$C$9 | F21: ='Assumptions'!$C$16 | G21: ='Assumptions'!$C$10+'Assumptions'!$C$11+IF('Assumptions'!$C$13>0,'Assumptions'!$C$13,'Assumptions'!$C$12/F21) | H21: ='Assumptions'!$C$31-'Assumptions'!$C$55 | I21: ='Assumptions'!$C$25 | J21: ='Assumptions'!$C$27 | K21: ='Assumptions'!$C$29 | L21: ='Assumptions'!$C$30+'Assumptions'!$C$55 | M21: ='Assumptions'!$C$25/'Assumptions'!$C$26-1 | N21: =F21*G21 | O21: =N21+H21 | P21: =IF(K21>0,N21/K21,"n.m.") | Q21: =IF(J21>0,O21/J21,"n.m.") | R21: =IF(L21>0,N21/L21,"n.m.") | S21: =J21/I21 | T21: =K21/L21
B23: Premium / (discount) to peer median at cap | P23: =IFERROR(P21/P14-1,"") | Q23: =IFERROR(Q21/Q14-1,"") | R23: =IFERROR(R21/R14-1,"")
B25: Peer basis must match the issuer: post-issue diluted, consolidated vs standalone consistent. Where the RHP gives no peers, build your own and disclose the set as ours.
B26: Also anchor to recent comparable IPO pricings on the same platform where available.

Sheet Relative
A1: Relative valuation - peer median multiples applied to the issuer
A2: Parshwanath Capital Ventures Fund | SEBI Registered CAT III AIF | IN/AIF3/25-26/2108 | Fund Manager: CA Deep Dalal | Sponsor: Jignesh Shah
B4: Method | C4: Peer median | D4: Issuer metric | E4: Implied equity (Rs cr) | F4: Value / share (Rs) | G4: Weight | H4: Usable weight | I4: Weighted value
B5: P/E x PAT | C5: =Peers!P14 | D5: ='Assumptions'!$C$29 | E5: =IF(ISNUMBER(C5),C5*D5,"") | F5: =IF(ISNUMBER(E5),E5/'Assumptions'!$C$56,"") | G5: ='Assumptions'!$C$49 | H5: =IF(ISNUMBER(F5),G5,0) | I5: =IF(ISNUMBER(F5),F5*G5,0)
B6: EV/EBITDA x EBITDA - net debt + net proceeds | C6: =Peers!Q14 | D6: ='Assumptions'!$C$27 | E6: =IF(ISNUMBER(C6),C6*D6-'Assumptions'!$C$31+'Assumptions'!$C$55,"") | F6: =IF(ISNUMBER(E6),E6/'Assumptions'!$C$56,"") | G6: ='Assumptions'!$C$50 | H6: =IF(ISNUMBER(F6),G6,0) | I6: =IF(ISNUMBER(F6),F6*G6,0)
B7: P/B x post-issue net worth | C7: =Peers!R14 | D7: ='Assumptions'!$C$30+'Assumptions'!$C$55 | E7: =IF(ISNUMBER(C7),C7*D7,"") | F7: =IF(ISNUMBER(E7),E7/'Assumptions'!$C$56,"") | G7: ='Assumptions'!$C$51 | H7: =IF(ISNUMBER(F7),G7,0) | I7: =IF(ISNUMBER(F7),F7*G7,0)
B9: Weighted value per share (pre-discount) | F9: =IF(SUM(H5:H7)=0,"n.a.",SUM(I5:I7)/SUM(H5:H7))
B10: Discount to peer median | F10: ='Assumptions'!$C$52
B11: Relative value per share (Rs) | F11: =IF(ISNUMBER(F9),F9*(1-F10),"n.a.")
B13: Relative prices reported earnings; DCF prices cash. A large gap between them is the finding.

Sheet ReverseDCF
A1: Reverse DCF - what the price asks for, one lever at a time
A2: Parshwanath Capital Ventures Fund | SEBI Registered CAT III AIF | IN/AIF3/25-26/2108 | Fund Manager: CA Deep Dalal | Sponsor: Jignesh Shah
B4: Item | C4: At floor | D4: At cap | E4: Actual / model
B5: Price (Rs) | C5: ='Assumptions'!$C$15 | D5: ='Assumptions'!$C$16
B6: Market cap (Rs cr) | C6: ='Assumptions'!$C$15*('Assumptions'!$C$10+'Assumptions'!$C$11+IF('Assumptions'!$C$13>0,'Assumptions'!$C$13,'Assumptions'!$C$12/'Assumptions'!$C$15)) | D6: ='Assumptions'!$C$16*('Assumptions'!$C$10+'Assumptions'!$C$11+IF('Assumptions'!$C$13>0,'Assumptions'!$C$13,'Assumptions'!$C$12/'Assumptions'!$C$16))
B7: Implied EV = mcap + net debt - net proceeds | C7: =C6+'Assumptions'!$C$31-'Assumptions'!$C$55 | D7: =D6+'Assumptions'!$C$31-'Assumptions'!$C$55
B8: Current FCFF (Y0 actual) | C8: =DCF!$C$18 | D8: =DCF!$C$18
B9: EV / current FCFF | C9: =IF(C8<=0,"No multiple: FCF negative - the price assumes cash generation improves",C7/C8) | D9: =IF(D8<=0,"No multiple: FCF negative - the price assumes cash generation improves",D7/D8)
B11: Lever 1 - implied perpetual growth on current FCFF | C11: =IF(C8<=0,"n.m. (FCF negative)",(C7*'Assumptions'!$C$60-C8)/(C7+C8)) | D11: =IF(D8<=0,"n.m. (FCF negative)",(D7*'Assumptions'!$C$60-D8)/(D7+D8)) | E11: ='Assumptions'!$C$45 | F11: terminal g used
B12: Lever 2 - implied WACC at terminal g | C12: =IF(C8<=0,"n.m. (FCF negative)",C8*(1+'Assumptions'!$C$45)/C7+'Assumptions'!$C$45) | D12: =IF(D8<=0,"n.m. (FCF negative)",D8*(1+'Assumptions'!$C$45)/D7+'Assumptions'!$C$45) | E12: ='Assumptions'!$C$60 | F12: model WACC
B13: Lever 3 - required EBIT margin (steady state) | C13: =C7*('Assumptions'!$C$60-'Assumptions'!$C$45)/((1+'Assumptions'!$C$45)*(1-'Assumptions'!$C$45/Assumptions!$C$74))/(1-'Assumptions'!$C$35)/'Assumptions'!$C$25 | D13: =D7*('Assumptions'!$C$60-'Assumptions'!$C$45)/((1+'Assumptions'!$C$45)*(1-'Assumptions'!$C$45/Assumptions!$C$74))/(1-'Assumptions'!$C$35)/'Assumptions'!$C$25 | E13: =DCF!$C$11/DCF!$C$7 | F13: actual EBIT margin
B14: Lever 4 - required NWC % of revenue (steady state) | C14: =IF((DCF!$C$13-'Assumptions'!$C$62*'Assumptions'!$C$25*'Assumptions'!$C$45-C7*('Assumptions'!$C$60-'Assumptions'!$C$45)/(1+'Assumptions'!$C$45))<0,"Unreachable: needs negative working capital",(DCF!$C$13-'Assumptions'!$C$62*'Assumptions'!$C$25*'Assumptions'!$C$45-C7*('Assumptions'!$C$60-'Assumptions'!$C$45)/(1+'Assumptions'!$C$45))/('Assumptions'!$C$25*'Assumptions'!$C$45)) | D14: =IF((DCF!$C$13-'Assumptions'!$C$62*'Assumptions'!$C$25*'Assumptions'!$C$45-D7*('Assumptions'!$C$60-'Assumptions'!$C$45)/(1+'Assumptions'!$C$45))<0,"Unreachable: needs negative working capital",(DCF!$C$13-'Assumptions'!$C$62*'Assumptions'!$C$25*'Assumptions'!$C$45-D7*('Assumptions'!$C$60-'Assumptions'!$C$45)/(1+'Assumptions'!$C$45))/('Assumptions'!$C$25*'Assumptions'!$C$45)) | E14: ='Assumptions'!$C$32/'Assumptions'!$C$25 | F14: actual NWC %
B16: In plain words (at cap) | C16: =IF(D8<=0,"Current free cash flow is negative, so no multiple can be stated: the price assumes cash generation improves from here.","The price asks the business to deliver "&TEXT(D9,"0.0")&" times its current free cash flow, in perpetuity.")
B18: Levers 1-2 use actual Y0 FCFF (Gordon). Levers 3-4 use a steady state: capex = D&A + k x dRev, terminal reinvestment g/ROIC. One implausible lever is an argument; four is a conclusion.

Sheet Sensitivity
A1: Sensitivity - value per share (Rs)
A2: Parshwanath Capital Ventures Fund | SEBI Registered CAT III AIF | IN/AIF3/25-26/2108 | Fund Manager: CA Deep Dalal | Sponsor: Jignesh Shah
B4: Grid 1: WACC (rows) vs terminal growth (columns)
C5: ='Assumptions'!$C$45+-0.01 | D5: ='Assumptions'!$C$45+-0.005 | E5: ='Assumptions'!$C$45+0 | F5: ='Assumptions'!$C$45+0.005 | G5: ='Assumptions'!$C$45+0.01
B6: ='Assumptions'!$C$60+-0.02 | C6: =IF($B6-C$5<=0,"n.m.",(NPV($B6,DCF!$D$18:$H$18)+DCF!$H$13*(1+C$5)*(1-C$5/Assumptions!$C$74)/($B6-C$5)/(1+$B6)^5-'Assumptions'!$C$31+'Assumptions'!$C$58)/'Assumptions'!$C$56) | D6: =IF($B6-D$5<=0,"n.m.",(NPV($B6,DCF!$D$18:$H$18)+DCF!$H$13*(1+D$5)*(1-D$5/Assumptions!$C$74)/($B6-D$5)/(1+$B6)^5-'Assumptions'!$C$31+'Assumptions'!$C$58)/'Assumptions'!$C$56) | E6: =IF($B6-E$5<=0,"n.m.",(NPV($B6,DCF!$D$18:$H$18)+DCF!$H$13*(1+E$5)*(1-E$5/Assumptions!$C$74)/($B6-E$5)/(1+$B6)^5-'Assumptions'!$C$31+'Assumptions'!$C$58)/'Assumptions'!$C$56) | F6: =IF($B6-F$5<=0,"n.m.",(NPV($B6,DCF!$D$18:$H$18)+DCF!$H$13*(1+F$5)*(1-F$5/Assumptions!$C$74)/($B6-F$5)/(1+$B6)^5-'Assumptions'!$C$31+'Assumptions'!$C$58)/'Assumptions'!$C$56) | G6: =IF($B6-G$5<=0,"n.m.",(NPV($B6,DCF!$D$18:$H$18)+DCF!$H$13*(1+G$5)*(1-G$5/Assumptions!$C$74)/($B6-G$5)/(1+$B6)^5-'Assumptions'!$C$31+'Assumptions'!$C$58)/'Assumptions'!$C$56)
B7: ='Assumptions'!$C$60+-0.01 | C7: =IF($B7-C$5<=0,"n.m.",(NPV($B7,DCF!$D$18:$H$18)+DCF!$H$13*(1+C$5)*(1-C$5/Assumptions!$C$74)/($B7-C$5)/(1+$B7)^5-'Assumptions'!$C$31+'Assumptions'!$C$58)/'Assumptions'!$C$56) | D7: =IF($B7-D$5<=0,"n.m.",(NPV($B7,DCF!$D$18:$H$18)+DCF!$H$13*(1+D$5)*(1-D$5/Assumptions!$C$74)/($B7-D$5)/(1+$B7)^5-'Assumptions'!$C$31+'Assumptions'!$C$58)/'Assumptions'!$C$56) | E7: =IF($B7-E$5<=0,"n.m.",(NPV($B7,DCF!$D$18:$H$18)+DCF!$H$13*(1+E$5)*(1-E$5/Assumptions!$C$74)/($B7-E$5)/(1+$B7)^5-'Assumptions'!$C$31+'Assumptions'!$C$58)/'Assumptions'!$C$56) | F7: =IF($B7-F$5<=0,"n.m.",(NPV($B7,DCF!$D$18:$H$18)+DCF!$H$13*(1+F$5)*(1-F$5/Assumptions!$C$74)/($B7-F$5)/(1+$B7)^5-'Assumptions'!$C$31+'Assumptions'!$C$58)/'Assumptions'!$C$56) | G7: =IF($B7-G$5<=0,"n.m.",(NPV($B7,DCF!$D$18:$H$18)+DCF!$H$13*(1+G$5)*(1-G$5/Assumptions!$C$74)/($B7-G$5)/(1+$B7)^5-'Assumptions'!$C$31+'Assumptions'!$C$58)/'Assumptions'!$C$56)
B8: ='Assumptions'!$C$60+0 | C8: =IF($B8-C$5<=0,"n.m.",(NPV($B8,DCF!$D$18:$H$18)+DCF!$H$13*(1+C$5)*(1-C$5/Assumptions!$C$74)/($B8-C$5)/(1+$B8)^5-'Assumptions'!$C$31+'Assumptions'!$C$58)/'Assumptions'!$C$56) | D8: =IF($B8-D$5<=0,"n.m.",(NPV($B8,DCF!$D$18:$H$18)+DCF!$H$13*(1+D$5)*(1-D$5/Assumptions!$C$74)/($B8-D$5)/(1+$B8)^5-'Assumptions'!$C$31+'Assumptions'!$C$58)/'Assumptions'!$C$56) | E8: =IF($B8-E$5<=0,"n.m.",(NPV($B8,DCF!$D$18:$H$18)+DCF!$H$13*(1+E$5)*(1-E$5/Assumptions!$C$74)/($B8-E$5)/(1+$B8)^5-'Assumptions'!$C$31+'Assumptions'!$C$58)/'Assumptions'!$C$56) | F8: =IF($B8-F$5<=0,"n.m.",(NPV($B8,DCF!$D$18:$H$18)+DCF!$H$13*(1+F$5)*(1-F$5/Assumptions!$C$74)/($B8-F$5)/(1+$B8)^5-'Assumptions'!$C$31+'Assumptions'!$C$58)/'Assumptions'!$C$56) | G8: =IF($B8-G$5<=0,"n.m.",(NPV($B8,DCF!$D$18:$H$18)+DCF!$H$13*(1+G$5)*(1-G$5/Assumptions!$C$74)/($B8-G$5)/(1+$B8)^5-'Assumptions'!$C$31+'Assumptions'!$C$58)/'Assumptions'!$C$56)
B9: ='Assumptions'!$C$60+0.01 | C9: =IF($B9-C$5<=0,"n.m.",(NPV($B9,DCF!$D$18:$H$18)+DCF!$H$13*(1+C$5)*(1-C$5/Assumptions!$C$74)/($B9-C$5)/(1+$B9)^5-'Assumptions'!$C$31+'Assumptions'!$C$58)/'Assumptions'!$C$56) | D9: =IF($B9-D$5<=0,"n.m.",(NPV($B9,DCF!$D$18:$H$18)+DCF!$H$13*(1+D$5)*(1-D$5/Assumptions!$C$74)/($B9-D$5)/(1+$B9)^5-'Assumptions'!$C$31+'Assumptions'!$C$58)/'Assumptions'!$C$56) | E9: =IF($B9-E$5<=0,"n.m.",(NPV($B9,DCF!$D$18:$H$18)+DCF!$H$13*(1+E$5)*(1-E$5/Assumptions!$C$74)/($B9-E$5)/(1+$B9)^5-'Assumptions'!$C$31+'Assumptions'!$C$58)/'Assumptions'!$C$56) | F9: =IF($B9-F$5<=0,"n.m.",(NPV($B9,DCF!$D$18:$H$18)+DCF!$H$13*(1+F$5)*(1-F$5/Assumptions!$C$74)/($B9-F$5)/(1+$B9)^5-'Assumptions'!$C$31+'Assumptions'!$C$58)/'Assumptions'!$C$56) | G9: =IF($B9-G$5<=0,"n.m.",(NPV($B9,DCF!$D$18:$H$18)+DCF!$H$13*(1+G$5)*(1-G$5/Assumptions!$C$74)/($B9-G$5)/(1+$B9)^5-'Assumptions'!$C$31+'Assumptions'!$C$58)/'Assumptions'!$C$56)
B10: ='Assumptions'!$C$60+0.02 | C10: =IF($B10-C$5<=0,"n.m.",(NPV($B10,DCF!$D$18:$H$18)+DCF!$H$13*(1+C$5)*(1-C$5/Assumptions!$C$74)/($B10-C$5)/(1+$B10)^5-'Assumptions'!$C$31+'Assumptions'!$C$58)/'Assumptions'!$C$56) | D10: =IF($B10-D$5<=0,"n.m.",(NPV($B10,DCF!$D$18:$H$18)+DCF!$H$13*(1+D$5)*(1-D$5/Assumptions!$C$74)/($B10-D$5)/(1+$B10)^5-'Assumptions'!$C$31+'Assumptions'!$C$58)/'Assumptions'!$C$56) | E10: =IF($B10-E$5<=0,"n.m.",(NPV($B10,DCF!$D$18:$H$18)+DCF!$H$13*(1+E$5)*(1-E$5/Assumptions!$C$74)/($B10-E$5)/(1+$B10)^5-'Assumptions'!$C$31+'Assumptions'!$C$58)/'Assumptions'!$C$56) | F10: =IF($B10-F$5<=0,"n.m.",(NPV($B10,DCF!$D$18:$H$18)+DCF!$H$13*(1+F$5)*(1-F$5/Assumptions!$C$74)/($B10-F$5)/(1+$B10)^5-'Assumptions'!$C$31+'Assumptions'!$C$58)/'Assumptions'!$C$56) | G10: =IF($B10-G$5<=0,"n.m.",(NPV($B10,DCF!$D$18:$H$18)+DCF!$H$13*(1+G$5)*(1-G$5/Assumptions!$C$74)/($B10-G$5)/(1+$B10)^5-'Assumptions'!$C$31+'Assumptions'!$C$58)/'Assumptions'!$C$56)
B12: Grid 2: NWC % of revenue (rows) vs EBITDA margin (columns) - model WACC and g
C13: =Assumptions!$C$72+-0.02 | D13: =Assumptions!$C$72+-0.01 | E13: =Assumptions!$C$72+0 | F13: =Assumptions!$C$72+0.01 | G13: =Assumptions!$C$72+0.02
B14: =Assumptions!$C$73+-0.06 | C14: =DCF!$C$37+((C$13-Assumptions!$C$72)*(1-'Assumptions'!$C$35)*(SUMPRODUCT(DCF!$D$7:$H$7,DCF!$D$19:$H$19)+DCF!$H$7*(1+'Assumptions'!$C$45)*(1-'Assumptions'!$C$45/Assumptions!$C$74)/('Assumptions'!$C$60-'Assumptions'!$C$45)*DCF!$H$19)+SUMPRODUCT(DCF!$D$17:$H$17,DCF!$D$19:$H$19)-((DCF!$D$7*$B14-DCF!$C$16)*DCF!$D$19+$B14*SUMPRODUCT(DCF!$E$7:$H$7-DCF!$D$7:$G$7,DCF!$E$19:$H$19)))/'Assumptions'!$C$56 | D14: =DCF!$C$37+((D$13-Assumptions!$C$72)*(1-'Assumptions'!$C$35)*(SUMPRODUCT(DCF!$D$7:$H$7,DCF!$D$19:$H$19)+DCF!$H$7*(1+'Assumptions'!$C$45)*(1-'Assumptions'!$C$45/Assumptions!$C$74)/('Assumptions'!$C$60-'Assumptions'!$C$45)*DCF!$H$19)+SUMPRODUCT(DCF!$D$17:$H$17,DCF!$D$19:$H$19)-((DCF!$D$7*$B14-DCF!$C$16)*DCF!$D$19+$B14*SUMPRODUCT(DCF!$E$7:$H$7-DCF!$D$7:$G$7,DCF!$E$19:$H$19)))/'Assumptions'!$C$56 | E14: =DCF!$C$37+((E$13-Assumptions!$C$72)*(1-'Assumptions'!$C$35)*(SUMPRODUCT(DCF!$D$7:$H$7,DCF!$D$19:$H$19)+DCF!$H$7*(1+'Assumptions'!$C$45)*(1-'Assumptions'!$C$45/Assumptions!$C$74)/('Assumptions'!$C$60-'Assumptions'!$C$45)*DCF!$H$19)+SUMPRODUCT(DCF!$D$17:$H$17,DCF!$D$19:$H$19)-((DCF!$D$7*$B14-DCF!$C$16)*DCF!$D$19+$B14*SUMPRODUCT(DCF!$E$7:$H$7-DCF!$D$7:$G$7,DCF!$E$19:$H$19)))/'Assumptions'!$C$56 | F14: =DCF!$C$37+((F$13-Assumptions!$C$72)*(1-'Assumptions'!$C$35)*(SUMPRODUCT(DCF!$D$7:$H$7,DCF!$D$19:$H$19)+DCF!$H$7*(1+'Assumptions'!$C$45)*(1-'Assumptions'!$C$45/Assumptions!$C$74)/('Assumptions'!$C$60-'Assumptions'!$C$45)*DCF!$H$19)+SUMPRODUCT(DCF!$D$17:$H$17,DCF!$D$19:$H$19)-((DCF!$D$7*$B14-DCF!$C$16)*DCF!$D$19+$B14*SUMPRODUCT(DCF!$E$7:$H$7-DCF!$D$7:$G$7,DCF!$E$19:$H$19)))/'Assumptions'!$C$56 | G14: =DCF!$C$37+((G$13-Assumptions!$C$72)*(1-'Assumptions'!$C$35)*(SUMPRODUCT(DCF!$D$7:$H$7,DCF!$D$19:$H$19)+DCF!$H$7*(1+'Assumptions'!$C$45)*(1-'Assumptions'!$C$45/Assumptions!$C$74)/('Assumptions'!$C$60-'Assumptions'!$C$45)*DCF!$H$19)+SUMPRODUCT(DCF!$D$17:$H$17,DCF!$D$19:$H$19)-((DCF!$D$7*$B14-DCF!$C$16)*DCF!$D$19+$B14*SUMPRODUCT(DCF!$E$7:$H$7-DCF!$D$7:$G$7,DCF!$E$19:$H$19)))/'Assumptions'!$C$56
B15: =Assumptions!$C$73+-0.03 | C15: =DCF!$C$37+((C$13-Assumptions!$C$72)*(1-'Assumptions'!$C$35)*(SUMPRODUCT(DCF!$D$7:$H$7,DCF!$D$19:$H$19)+DCF!$H$7*(1+'Assumptions'!$C$45)*(1-'Assumptions'!$C$45/Assumptions!$C$74)/('Assumptions'!$C$60-'Assumptions'!$C$45)*DCF!$H$19)+SUMPRODUCT(DCF!$D$17:$H$17,DCF!$D$19:$H$19)-((DCF!$D$7*$B15-DCF!$C$16)*DCF!$D$19+$B15*SUMPRODUCT(DCF!$E$7:$H$7-DCF!$D$7:$G$7,DCF!$E$19:$H$19)))/'Assumptions'!$C$56 | D15: =DCF!$C$37+((D$13-Assumptions!$C$72)*(1-'Assumptions'!$C$35)*(SUMPRODUCT(DCF!$D$7:$H$7,DCF!$D$19:$H$19)+DCF!$H$7*(1+'Assumptions'!$C$45)*(1-'Assumptions'!$C$45/Assumptions!$C$74)/('Assumptions'!$C$60-'Assumptions'!$C$45)*DCF!$H$19)+SUMPRODUCT(DCF!$D$17:$H$17,DCF!$D$19:$H$19)-((DCF!$D$7*$B15-DCF!$C$16)*DCF!$D$19+$B15*SUMPRODUCT(DCF!$E$7:$H$7-DCF!$D$7:$G$7,DCF!$E$19:$H$19)))/'Assumptions'!$C$56 | E15: =DCF!$C$37+((E$13-Assumptions!$C$72)*(1-'Assumptions'!$C$35)*(SUMPRODUCT(DCF!$D$7:$H$7,DCF!$D$19:$H$19)+DCF!$H$7*(1+'Assumptions'!$C$45)*(1-'Assumptions'!$C$45/Assumptions!$C$74)/('Assumptions'!$C$60-'Assumptions'!$C$45)*DCF!$H$19)+SUMPRODUCT(DCF!$D$17:$H$17,DCF!$D$19:$H$19)-((DCF!$D$7*$B15-DCF!$C$16)*DCF!$D$19+$B15*SUMPRODUCT(DCF!$E$7:$H$7-DCF!$D$7:$G$7,DCF!$E$19:$H$19)))/'Assumptions'!$C$56 | F15: =DCF!$C$37+((F$13-Assumptions!$C$72)*(1-'Assumptions'!$C$35)*(SUMPRODUCT(DCF!$D$7:$H$7,DCF!$D$19:$H$19)+DCF!$H$7*(1+'Assumptions'!$C$45)*(1-'Assumptions'!$C$45/Assumptions!$C$74)/('Assumptions'!$C$60-'Assumptions'!$C$45)*DCF!$H$19)+SUMPRODUCT(DCF!$D$17:$H$17,DCF!$D$19:$H$19)-((DCF!$D$7*$B15-DCF!$C$16)*DCF!$D$19+$B15*SUMPRODUCT(DCF!$E$7:$H$7-DCF!$D$7:$G$7,DCF!$E$19:$H$19)))/'Assumptions'!$C$56 | G15: =DCF!$C$37+((G$13-Assumptions!$C$72)*(1-'Assumptions'!$C$35)*(SUMPRODUCT(DCF!$D$7:$H$7,DCF!$D$19:$H$19)+DCF!$H$7*(1+'Assumptions'!$C$45)*(1-'Assumptions'!$C$45/Assumptions!$C$74)/('Assumptions'!$C$60-'Assumptions'!$C$45)*DCF!$H$19)+SUMPRODUCT(DCF!$D$17:$H$17,DCF!$D$19:$H$19)-((DCF!$D$7*$B15-DCF!$C$16)*DCF!$D$19+$B15*SUMPRODUCT(DCF!$E$7:$H$7-DCF!$D$7:$G$7,DCF!$E$19:$H$19)))/'Assumptions'!$C$56
B16: =Assumptions!$C$73+0 | C16: =DCF!$C$37+((C$13-Assumptions!$C$72)*(1-'Assumptions'!$C$35)*(SUMPRODUCT(DCF!$D$7:$H$7,DCF!$D$19:$H$19)+DCF!$H$7*(1+'Assumptions'!$C$45)*(1-'Assumptions'!$C$45/Assumptions!$C$74)/('Assumptions'!$C$60-'Assumptions'!$C$45)*DCF!$H$19)+SUMPRODUCT(DCF!$D$17:$H$17,DCF!$D$19:$H$19)-((DCF!$D$7*$B16-DCF!$C$16)*DCF!$D$19+$B16*SUMPRODUCT(DCF!$E$7:$H$7-DCF!$D$7:$G$7,DCF!$E$19:$H$19)))/'Assumptions'!$C$56 | D16: =DCF!$C$37+((D$13-Assumptions!$C$72)*(1-'Assumptions'!$C$35)*(SUMPRODUCT(DCF!$D$7:$H$7,DCF!$D$19:$H$19)+DCF!$H$7*(1+'Assumptions'!$C$45)*(1-'Assumptions'!$C$45/Assumptions!$C$74)/('Assumptions'!$C$60-'Assumptions'!$C$45)*DCF!$H$19)+SUMPRODUCT(DCF!$D$17:$H$17,DCF!$D$19:$H$19)-((DCF!$D$7*$B16-DCF!$C$16)*DCF!$D$19+$B16*SUMPRODUCT(DCF!$E$7:$H$7-DCF!$D$7:$G$7,DCF!$E$19:$H$19)))/'Assumptions'!$C$56 | E16: =DCF!$C$37+((E$13-Assumptions!$C$72)*(1-'Assumptions'!$C$35)*(SUMPRODUCT(DCF!$D$7:$H$7,DCF!$D$19:$H$19)+DCF!$H$7*(1+'Assumptions'!$C$45)*(1-'Assumptions'!$C$45/Assumptions!$C$74)/('Assumptions'!$C$60-'Assumptions'!$C$45)*DCF!$H$19)+SUMPRODUCT(DCF!$D$17:$H$17,DCF!$D$19:$H$19)-((DCF!$D$7*$B16-DCF!$C$16)*DCF!$D$19+$B16*SUMPRODUCT(DCF!$E$7:$H$7-DCF!$D$7:$G$7,DCF!$E$19:$H$19)))/'Assumptions'!$C$56 | F16: =DCF!$C$37+((F$13-Assumptions!$C$72)*(1-'Assumptions'!$C$35)*(SUMPRODUCT(DCF!$D$7:$H$7,DCF!$D$19:$H$19)+DCF!$H$7*(1+'Assumptions'!$C$45)*(1-'Assumptions'!$C$45/Assumptions!$C$74)/('Assumptions'!$C$60-'Assumptions'!$C$45)*DCF!$H$19)+SUMPRODUCT(DCF!$D$17:$H$17,DCF!$D$19:$H$19)-((DCF!$D$7*$B16-DCF!$C$16)*DCF!$D$19+$B16*SUMPRODUCT(DCF!$E$7:$H$7-DCF!$D$7:$G$7,DCF!$E$19:$H$19)))/'Assumptions'!$C$56 | G16: =DCF!$C$37+((G$13-Assumptions!$C$72)*(1-'Assumptions'!$C$35)*(SUMPRODUCT(DCF!$D$7:$H$7,DCF!$D$19:$H$19)+DCF!$H$7*(1+'Assumptions'!$C$45)*(1-'Assumptions'!$C$45/Assumptions!$C$74)/('Assumptions'!$C$60-'Assumptions'!$C$45)*DCF!$H$19)+SUMPRODUCT(DCF!$D$17:$H$17,DCF!$D$19:$H$19)-((DCF!$D$7*$B16-DCF!$C$16)*DCF!$D$19+$B16*SUMPRODUCT(DCF!$E$7:$H$7-DCF!$D$7:$G$7,DCF!$E$19:$H$19)))/'Assumptions'!$C$56
B17: =Assumptions!$C$73+0.03 | C17: =DCF!$C$37+((C$13-Assumptions!$C$72)*(1-'Assumptions'!$C$35)*(SUMPRODUCT(DCF!$D$7:$H$7,DCF!$D$19:$H$19)+DCF!$H$7*(1+'Assumptions'!$C$45)*(1-'Assumptions'!$C$45/Assumptions!$C$74)/('Assumptions'!$C$60-'Assumptions'!$C$45)*DCF!$H$19)+SUMPRODUCT(DCF!$D$17:$H$17,DCF!$D$19:$H$19)-((DCF!$D$7*$B17-DCF!$C$16)*DCF!$D$19+$B17*SUMPRODUCT(DCF!$E$7:$H$7-DCF!$D$7:$G$7,DCF!$E$19:$H$19)))/'Assumptions'!$C$56 | D17: =DCF!$C$37+((D$13-Assumptions!$C$72)*(1-'Assumptions'!$C$35)*(SUMPRODUCT(DCF!$D$7:$H$7,DCF!$D$19:$H$19)+DCF!$H$7*(1+'Assumptions'!$C$45)*(1-'Assumptions'!$C$45/Assumptions!$C$74)/('Assumptions'!$C$60-'Assumptions'!$C$45)*DCF!$H$19)+SUMPRODUCT(DCF!$D$17:$H$17,DCF!$D$19:$H$19)-((DCF!$D$7*$B17-DCF!$C$16)*DCF!$D$19+$B17*SUMPRODUCT(DCF!$E$7:$H$7-DCF!$D$7:$G$7,DCF!$E$19:$H$19)))/'Assumptions'!$C$56 | E17: =DCF!$C$37+((E$13-Assumptions!$C$72)*(1-'Assumptions'!$C$35)*(SUMPRODUCT(DCF!$D$7:$H$7,DCF!$D$19:$H$19)+DCF!$H$7*(1+'Assumptions'!$C$45)*(1-'Assumptions'!$C$45/Assumptions!$C$74)/('Assumptions'!$C$60-'Assumptions'!$C$45)*DCF!$H$19)+SUMPRODUCT(DCF!$D$17:$H$17,DCF!$D$19:$H$19)-((DCF!$D$7*$B17-DCF!$C$16)*DCF!$D$19+$B17*SUMPRODUCT(DCF!$E$7:$H$7-DCF!$D$7:$G$7,DCF!$E$19:$H$19)))/'Assumptions'!$C$56 | F17: =DCF!$C$37+((F$13-Assumptions!$C$72)*(1-'Assumptions'!$C$35)*(SUMPRODUCT(DCF!$D$7:$H$7,DCF!$D$19:$H$19)+DCF!$H$7*(1+'Assumptions'!$C$45)*(1-'Assumptions'!$C$45/Assumptions!$C$74)/('Assumptions'!$C$60-'Assumptions'!$C$45)*DCF!$H$19)+SUMPRODUCT(DCF!$D$17:$H$17,DCF!$D$19:$H$19)-((DCF!$D$7*$B17-DCF!$C$16)*DCF!$D$19+$B17*SUMPRODUCT(DCF!$E$7:$H$7-DCF!$D$7:$G$7,DCF!$E$19:$H$19)))/'Assumptions'!$C$56 | G17: =DCF!$C$37+((G$13-Assumptions!$C$72)*(1-'Assumptions'!$C$35)*(SUMPRODUCT(DCF!$D$7:$H$7,DCF!$D$19:$H$19)+DCF!$H$7*(1+'Assumptions'!$C$45)*(1-'Assumptions'!$C$45/Assumptions!$C$74)/('Assumptions'!$C$60-'Assumptions'!$C$45)*DCF!$H$19)+SUMPRODUCT(DCF!$D$17:$H$17,DCF!$D$19:$H$19)-((DCF!$D$7*$B17-DCF!$C$16)*DCF!$D$19+$B17*SUMPRODUCT(DCF!$E$7:$H$7-DCF!$D$7:$G$7,DCF!$E$19:$H$19)))/'Assumptions'!$C$56
B18: =Assumptions!$C$73+0.06 | C18: =DCF!$C$37+((C$13-Assumptions!$C$72)*(1-'Assumptions'!$C$35)*(SUMPRODUCT(DCF!$D$7:$H$7,DCF!$D$19:$H$19)+DCF!$H$7*(1+'Assumptions'!$C$45)*(1-'Assumptions'!$C$45/Assumptions!$C$74)/('Assumptions'!$C$60-'Assumptions'!$C$45)*DCF!$H$19)+SUMPRODUCT(DCF!$D$17:$H$17,DCF!$D$19:$H$19)-((DCF!$D$7*$B18-DCF!$C$16)*DCF!$D$19+$B18*SUMPRODUCT(DCF!$E$7:$H$7-DCF!$D$7:$G$7,DCF!$E$19:$H$19)))/'Assumptions'!$C$56 | D18: =DCF!$C$37+((D$13-Assumptions!$C$72)*(1-'Assumptions'!$C$35)*(SUMPRODUCT(DCF!$D$7:$H$7,DCF!$D$19:$H$19)+DCF!$H$7*(1+'Assumptions'!$C$45)*(1-'Assumptions'!$C$45/Assumptions!$C$74)/('Assumptions'!$C$60-'Assumptions'!$C$45)*DCF!$H$19)+SUMPRODUCT(DCF!$D$17:$H$17,DCF!$D$19:$H$19)-((DCF!$D$7*$B18-DCF!$C$16)*DCF!$D$19+$B18*SUMPRODUCT(DCF!$E$7:$H$7-DCF!$D$7:$G$7,DCF!$E$19:$H$19)))/'Assumptions'!$C$56 | E18: =DCF!$C$37+((E$13-Assumptions!$C$72)*(1-'Assumptions'!$C$35)*(SUMPRODUCT(DCF!$D$7:$H$7,DCF!$D$19:$H$19)+DCF!$H$7*(1+'Assumptions'!$C$45)*(1-'Assumptions'!$C$45/Assumptions!$C$74)/('Assumptions'!$C$60-'Assumptions'!$C$45)*DCF!$H$19)+SUMPRODUCT(DCF!$D$17:$H$17,DCF!$D$19:$H$19)-((DCF!$D$7*$B18-DCF!$C$16)*DCF!$D$19+$B18*SUMPRODUCT(DCF!$E$7:$H$7-DCF!$D$7:$G$7,DCF!$E$19:$H$19)))/'Assumptions'!$C$56 | F18: =DCF!$C$37+((F$13-Assumptions!$C$72)*(1-'Assumptions'!$C$35)*(SUMPRODUCT(DCF!$D$7:$H$7,DCF!$D$19:$H$19)+DCF!$H$7*(1+'Assumptions'!$C$45)*(1-'Assumptions'!$C$45/Assumptions!$C$74)/('Assumptions'!$C$60-'Assumptions'!$C$45)*DCF!$H$19)+SUMPRODUCT(DCF!$D$17:$H$17,DCF!$D$19:$H$19)-((DCF!$D$7*$B18-DCF!$C$16)*DCF!$D$19+$B18*SUMPRODUCT(DCF!$E$7:$H$7-DCF!$D$7:$G$7,DCF!$E$19:$H$19)))/'Assumptions'!$C$56 | G18: =DCF!$C$37+((G$13-Assumptions!$C$72)*(1-'Assumptions'!$C$35)*(SUMPRODUCT(DCF!$D$7:$H$7,DCF!$D$19:$H$19)+DCF!$H$7*(1+'Assumptions'!$C$45)*(1-'Assumptions'!$C$45/Assumptions!$C$74)/('Assumptions'!$C$60-'Assumptions'!$C$45)*DCF!$H$19)+SUMPRODUCT(DCF!$D$17:$H$17,DCF!$D$19:$H$19)-((DCF!$D$7*$B18-DCF!$C$16)*DCF!$D$19+$B18*SUMPRODUCT(DCF!$E$7:$H$7-DCF!$D$7:$G$7,DCF!$E$19:$H$19)))/'Assumptions'!$C$56
B20: Centre cells (yellow) equal the DCF value. Working capital is often the dominant lever - if Grid 2 moves value more than Grid 1, say so in the note.
